Workbook
Name BTY: 'THP2'!$B$8:$J$8
Name CCSC: 'THP2'!$B$15:$J$15
Name CCSEl: 'THP2'!$B$17:$J$17
Name CCSLT: 'THP2'!$B$16:$J$16
Name CO2F: UNIT!$M$2:$M$1393
Name COAL: UNIT!$A$5
Name EXIU: UNIT!$U$2:$U$1393
Name EXU: UNIT!$T$2:$T$1393
Name FCC: 'Fuel & Resister'!$B$6:$G$6
Name FCT: 'Fuel & Resister'!$B$4:$G$4
Name FF: 'Fuel & Resister'!$B$1
Name FHC: 'Fuel & Resister'!$B$5:$G$5
Name FTY: 'Fuel & Resister'!$B$3:$G$3
Name HR: UNIT!$K$2:$L$1393
Name LFC: 'THP2'!$B$13:$J$13
Name LFCR: UNIT!$P$2:$P$1393
Name LNG: UNIT!$A$9
Name M: 'Usage Rate'!$D$3
Name MDY: 'THP2'!$B$14:$J$14
Name MO: 'THP2'!$B$12:$J$12
Name MOL: UNIT!$H$2:$H$1393
Name MS: 'THP2'!$B$11:$J$11
Name MSD: UNIT!$O$2:$O$1393
Name MXU: UNIT!$S$2:$S$1393
Name NUCLEAR: UNIT!$A$13
Name OCR: UNIT!$J$2:$J$1393
Name OIL: UNIT!$A$17
Name PEF: UNIT!$L$2:$L$1393
Name PLO: UNIT!$K$2:$K$1393
Name PLT: 'THP2'!$B$6:$J$6
Name PN: UNIT!$C$2:$C$1393
Name POM: 'THP2'!$B$7:$J$7
Name PP: UNIT!$A$2
Name PTY: UNIT!$G$2:$G$1393
Name PTYN: 'THP2'!$A$3
Name PUC: 'THP2'!$B$5:$J$5
Name REG: 'THP2'!$B$9:$J$10
Name RFC: 'Fuel & Resister'!$J$2:$J$3
Name SC: 'THP2'!$B$13:$J$13
Name STUC: UNIT!$N$2:$N$1393
Name SYN: UNIT!$Q$2:$Q$1393
Name UCAP: UNIT!$I$2:$I$1393
Name UR: 'Usage Rate'!$F$5:$I$369
Name USR: 'Usage Rate'!$E$5:$J$369

Sheet UNIT
C1: Node | D1: Type | E1: Name | G1: Plant Type | H1: Minimum Output Level | I1: Unit Capacity [GW/unit] | J1: Own Consumption Rate | K1: Heat Rate(Minimum load)[Mcal/kWh] | L1: Heat Rate [Mcal/kWh] | M1: Maximum CO2 flow[Mt-CO2/year] | N1: Start-up cost [million Yen] | O1: Start date of Maintenance | P1: LFC rate | Q1: Synchronous Inertia [s] | R1: CCS flag (1:installable 0:not) | S1: Maximum Unit Number | T1: Exsiting Unit Number | U1: Exiciting Unit Parameter(for mixed fuel) | W1: 最低出力 | Y1: 所内率 | Z1: ヒートレート（最低出力時） | AA1: ヒートレート（定格時） | AB1: 起動費 | AC1: 補修日数 | AD1: 最低負荷時効率 | AE1: 効率 | AI1: co2 intensity [kg/unit] | AJ1: heat content[Mcal/unit] | AO1: Maximum Unit Number | AP1: Exsiting Unit Number
A2: =ROWS(PN) -> 1392 | B2: msb | C2: =VLOOKUP(B2,[1]SYS!$F$5:$G$359,2,FALSE) -> 3 | D2: Coal | E2: 1ATUMA4 | F2: 苫東厚真発電所 | G2: 1 | H2: =W2/X2 -> 0.15 | I2: =X2/1000 -> 0.7 | J2: =1-Y2 -> 0.05 | K2: =Z2/1000 -> 2.82944 | L2: =AA2/1000 -> 1.99927 | M2: =(I2*10^6*L2/AJ2*AI2/10^6)*24*365/1000 -> 4.368666 | N2: 7.28 | O2: 403 | P2: 0.05 | Q2: 8 | R2: 1 | S2: 1 | T2: 0 | U2: 1 | V2: 1 | W2: 105 | X2: 700 | Y2: 0.95 | Z2: 2829.44 | AA2: 1999.27 | AB2: 728 | AC2: 55 | AD2: =1/Z2*860 -> 0.30394707 | AE2: =1/AA2*860 -> 0.43015701 | AF2: =(L2-H2*K2)/(1-H2) -> 1.8527694 | AG2: =I2*(L2-AF2) -> 0.10255041 | AH2: =AB2/100 -> 7.28 | AI2: =HLOOKUP(HLOOKUP(G2,'THP2'!$B$4:$J$8,5,FALSE),'Fuel & Resister'!$B$3:$G$6,4,FALSE) -> 2.26424 | AJ2: =HLOOKUP(HLOOKUP(G2,'THP2'!$B$4:$J$8,5,FALSE),'Fuel & Resister'!$B$3:$G$6,3,FALSE) -> 6.354 | AK2: =0.85985/L2 -> 0.43008198 | AL2: =405*24*365*0.7 -> 2483460 | AM2: =14761/126.5 -> 116.68775 | AO2: 1 | AP2: 1
B3: msb | C3: =VLOOKUP(B3,[1]SYS!$F$5:$G$359,2,FALSE) -> 3 | D3: Coal | E3: 1SN-TMK | G3: 1 | H3: =W3/X3 -> 0.3 | I3: =X3/1000 -> 0.02 | J3: =1-Y3 -> 0 | K3: =Z3/1000 -> 2.60054 | L3: =AA3/1000 -> 2.16983 | M3: =(I3*10^6*L3/AJ3*AI3/10^6)*24*365/1000 -> 0.13546748 | N3: 0.16 | O3: 903 | P3: 0.05 | Q3: 8 | R3: 1 | S3: 1 | T3: 0 | U3: 1 | V3: 2 | W3: 6 | X3: 20 | Y3: 1 | Z3: 2600.54 | AA3: 2169.83 | AB3: 16 | AC3: 55 | AD3: =1/Z3*860 -> 0.33070055 | AE3: =1/AA3*860 -> 0.39634441 | AF3: =(L3-H3*K3)/(1-H3) -> 1.98524 | AG3: =I3*(L3-AF3) -> 0.0036918 | AH3: =AB3/100 -> 0.16 | AI3: =HLOOKUP(HLOOKUP(G3,'THP2'!$B$4:$J$8,5,FALSE),'Fuel & Resister'!$B$3:$G$6,4,FALSE) -> 2.26424 | AJ3: =HLOOKUP(HLOOKUP(G3,'THP2'!$B$4:$J$8,5,FALSE),'Fuel & Resister'!$B$3:$G$6,3,FALSE) -> 6.354 | AK3: =0.85985/L3 -> 0.39627528 | AM3: =41500/405 -> 102.46914 | AO3: 1 | AP3: 1
A4: coal | B4: msb | C4: =VLOOKUP(B4,[1]SYS!$F$5:$G$359,2,FALSE) -> 3 | D4: Coal | E4: 1IP-SEIT | F4: 日本製鉄室蘭製鉄所 | G4: 1 | H4: =W4/X4 -> 0.3 | I4: =X4/1000 -> 0.1 | J4: =1-Y4 -> 0.06 | K4: =Z4/1000 -> 2.6328 | L4: =AA4/1000 -> 2.19674 | M4: =(I4*10^6*L4/AJ4*AI4/10^6)*24*365/1000 -> 0.68573768 | N4: 0.8 | O4: 1004 | P4: 0 | Q4: 8 | R4: 1 | S4: 1 | T4: 0 | U4: 1 | V4: 3 | W4: 30 | X4: 100 | Y4: 0.94 | Z4: 2632.8 | AA4: 2196.74 | AB4: 80 | AC4: 55 | AD4: =1/Z4*860 -> 0.32664844 | AE4: =1/AA4*860 -> 0.39148921 | AF4: =(L4-H4*K4)/(1-H4) -> 2.0098571 | AG4: =I4*(L4-AF4) -> 0.018688286 | AH4: =AB4/100 -> 0.8 | AI4: =HLOOKUP(HLOOKUP(G4,'THP2'!$B$4:$J$8,5,FALSE),'Fuel & Resister'!$B$3:$G$6,4,FALSE) -> 2.26424 | AJ4: =HLOOKUP(HLOOKUP(G4,'THP2'!$B$4:$J$8,5,FALSE),'Fuel & Resister'!$B$3:$G$6,3,FALSE) -> 6.354 | AK4: =0.85985/L4 -> 0.39142092 | AO4: 1 | AP4: 1
A5: =ROWS(D2:D134) -> 133 | B5: msb | C5: =VLOOKUP(B5,[1]SYS!$F$5:$G$359,2,FALSE) -> 3 | D5: Coal | E5: 1IP-SEIS | F5: 日本製紙釧路工場 | G5: 1 | H5: =W5/X5 -> 0.3 | I5: =X5/1000 -> 0.18 | J5: =1-Y5 -> 0.06 | K5: =Z5/1000 -> 2.6328 | L5: =AA5/1000 -> 2.19674 | M5: =(I5*10^6*L5/AJ5*AI5/10^6)*24*365/1000 -> 1.2343278 | N5: 1.44 | O5: 903 | P5: 0 | Q5: 8 | R5: 1 | S5: 1 | T5: 0 | U5: 1 | V5: 4 | W5: 54 | X5: 180 | Y5: 0.94 | Z5: 2632.8 | AA5: 2196.74 | AB5: 144 | AC5: 55 | AD5: =1/Z5*860 -> 0.32664844 | AE5: =1/AA5*860 -> 0.39148921 | AF5: =(L5-H5*K5)/(1-H5) -> 2.0098571 | AG5: =I5*(L5-AF5) -> 0.033638914 | AH5: =AB5/100 -> 1.44 | AI5: =HLOOKUP(HLOOKUP(G5,'THP2'!$B$4:$J$8,5,FALSE),'Fuel & Resister'!$B$3:$G$6,4,FALSE) -> 2.26424 | AJ5: =HLOOKUP(HLOOKUP(G5,'THP2'!$B$4:$J$8,5,FALSE),'Fuel & Resister'!$B$3:$G$6,3,FALSE) -> 6.354 | AK5: =0.85985/L5 -> 0.39142092 | AO5: 1 | AP5: 1
B6: akt | C6: =VLOOKUP(B6,[1]SYS!$F$5:$G$359,2,FALSE) -> 40 | D6: Coal | E6: 2AKITAM1 | F6: 秋田港発電所 | G6: 1 | H6: =W6/X6 -> 0.3 | I6: =X6/1000 -> 0.65 | J6: =1-Y6 -> 0.062 | K6: =Z6/1000 -> 2.397 | L6: =AA6/1000 -> 2 | M6: =(I6*10^6*L6/AJ6*AI6/10^6)*24*365/1000 -> 4.0580996 | N6: 6.7125 | O6: 403 | P6: 0.05 | Q6: 8 | R6: 1 | S6: 1 | T6: 0 | U6: 1 | V6: 5 | W6: 195 | X6: 650 | Y6: 0.938 | Z6: 2397 | AA6: 2000 | AB6: 671.25 | AC6: 55 | AD6: =1/Z6*860 -> 0.35878181 | AE6: =1/AA6*860 -> 0.43 | AF6: =(L6-H6*K6)/(1-H6) -> 1.8298571 | AG6: =I6*(L6-AF6) -> 0.11059286 | AH6: =AB6/100 -> 6.7125 | AI6: =HLOOKUP(HLOOKUP(G6,'THP2'!$B$4:$J$8,5,FALSE),'Fuel & Resister'!$B$3:$G$6,4,FALSE) -> 2.26424 | AJ6: =HLOOKUP(HLOOKUP(G6,'THP2'!$B$4:$J$8,5,FALSE),'Fuel & Resister'!$B$3:$G$6,3,FALSE) -> 6.354 | AK6: =0.85985/L6 -> 0.429925 | AO6: 1 | AP6: 1
B7: akt | C7: =VLOOKUP(B7,[1]SYS!$F$5:$G$359,2,FALSE) -> 40 | D7: Coal | E7: 2AKITAM2 | F7: 秋田港発電所 | G7: 1 | H7: =W7/X7 -> 0.3 | I7: =X7/1000 -> 0.65 | J7: =1-Y7 -> 0.062 | K7: =Z7/1000 -> 2.397 | L7: =AA7/1000 -> 2 | M7: =(I7*10^6*L7/AJ7*AI7/10^6)*24*365/1000 -> 4.0580996 | N7: 6.7125 | O7: 903 | P7: 0.05 | Q7: 8 | R7: 1 | S7: 1 | T7: 0 | U7: 1 | V7: 6 | W7: 195 | X7: 650 | Y7: 0.938 | Z7: 2397 | AA7: 2000 | AB7: 671.25 | AC7: 55 | AD7: =1/Z7*860 -> 0.35878181 | AE7: =1/AA7*860 -> 0.43 | AF7: =(L7-H7*K7)/(1-H7) -> 1.8298571 | AG7: =I7*(L7-AF7) -> 0.11059286 | AH7: =AB7/100 -> 6.7125 | AI7: =HLOOKUP(HLOOKUP(G7,'THP2'!$B$4:$J$8,5,FALSE),'Fuel & Resister'!$B$3:$G$6,4,FALSE) -> 2.26424 | AJ7: =HLOOKUP(HLOOKUP(G7,'THP2'!$B$4:$J$8,5,FALSE),'Fuel & Resister'!$B$3:$G$6,3,FALSE) -> 6.354 | AO7: 1 | AP7: 1
A8: LNG | B8: nsr | C8: =VLOOKUP(B8,[1]SYS!$F$5:$G$359,2,FALSE) -> 39 | D8: Coal | E8: 2NOSHIR3 | F8: 能代火力発電所 | G8: 1 | H8: =W8/X8 -> 0.3 | I8: =X8/1000 -> 0.6 | J8: =1-Y8 -> 0.0517 | K8: =Z8/1000 -> 2.397 | L8: =AA8/1000 -> 2 | M8: =(I8*10^6*L8/AJ8*AI8/10^6)*24*365/1000 -> 3.7459381 | N8: 6.145 | O8: 903 | P8: 0.05 | Q8: 8 | R8: 1 | S8: 1 | T8: 0 | U8: 1 | V8: 7 | W8: 180 | X8: 600 | Y8: 0.9483 | Z8: 2397 | AA8: 2000 | AB8: 614.5 | AC8: 55 | AD8: =1/Z8*860 -> 0.35878181 | AE8: =1/AA8*860 -> 0.43 | AF8: =(L8-H8*K8)/(1-H8) -> 1.8298571 | AG8: =I8*(L8-AF8) -> 0.10208571 | AH8: =AB8/100 -> 6.145 | AI8: =HLOOKUP(HLOOKUP(G8,'THP2'!$B$4:$J$8,5,FALSE),'Fuel & Resister'!$B$3:$G$6,4,FALSE) -> 2.26424 | AJ8: =HLOOKUP(HLOOKUP(G8,'THP2'!$B$4:$J$8,5,FALSE),'Fuel & Resister'!$B$3:$G$6,3,FALSE) -> 6.354 | AO8: 1 | AP8: 1
A9: =ROWS(D135:D446) -> 312 | B9: sfu | C9: =VLOOKUP(B9,[1]SYS!$F$5:$G$359,2,FALSE) -> 62 | D9: Coal | E9: 2HARAM2 | F9: 原町火力発電所 | G9: 1 | H9: =W9/X9 -> 0.187 | I9: =X9/1000 -> 1 | J9: =1-Y9 -> 0.053 | K9: =Z9/1000 -> 2.67542 | L9: =AA9/1000 -> 2.02793 | M9: =(I9*10^6*L9/AJ9*AI9/10^6)*24*365/1000 -> 6.3304169 | N9: 15 | O9: 403 | P9: 0.05 | Q9: 8 | R9: 1 | S9: 1 | T9: 0 | U9: 0 | V9: 8 | W9: 187 | X9: 1000 | Y9: 0.947 | Z9: 2675.42 | AA9: 2027.93 | AB9: 1500 | AC9: 55 | AD9: =1/Z9*860 -> 0.32144486 | AE9: =1/AA9*860 -> 0.42407775 | AF9: =(L9-H9*K9)/(1-H9) -> 1.8789993 | AG9: =I9*(L9-AF9) -> 0.14893066 | AH9: =AB9/100 -> 15 | AI9: =HLOOKUP(HLOOKUP(G9,'THP2'!$B$4:$J$8,5,FALSE),'Fuel & Resister'!$B$3:$G$6,4,FALSE) -> 2.26424 | AJ9: =HLOOKUP(HLOOKUP(G9,'THP2'!$B$4:$J$8,5,FALSE),'Fuel & Resister'!$B$3:$G$6,3,FALSE) -> 6.354 | AO9: 0 | AP9: 0
B10: sfu | C10: =VLOOKUP(B10,[1]SYS!$F$5:$G$359,2,FALSE) -> 62 | D10: Coal | E10: 2HARAM1 | F10: 原町火力発電所 | G10: 1 | H10: =W10/X10 -> 0.162 | I10: =X10/1000 -> 1 | J10: =1-Y10 -> 0.056 | K10: =Z10/1000 -> 2.87622 | L10: =AA10/1000 -> 2.03233 | M10: =(I10*10^6*L10/AJ10*AI10/10^6)*24*365/1000 -> 6.344152 | N10: 15 | O10: 504 | P10: 0.05 | Q10: 8 | R10: 1 | S10: 1 | T10: 0 | U10: 0 | V10: 9 | W10: 162 | X10: 1000 | Y10: 0.944 | Z10: 2876.22 | AA10: 2032.33 | AB10: 1500 | AC10: 55 | AD10: =1/Z10*860 -> 0.29900355 | AE10: =1/AA10*860 -> 0.42315962 | AF10: =(L10-H10*K10)/(1-H10) -> 1.8691914 | AG10: =I10*(L10-AF10) -> 0.16313864 | AH10: =AB10/100 -> 15 | AI10: =HLOOKUP(HLOOKUP(G10,'THP2'!$B$4:$J$8,5,FALSE),'Fuel & Resister'!$B$3:$G$6,4,FALSE) -> 2.26424 | AJ10: =HLOOKUP(HLOOKUP(G10,'THP2'!$B$4:$J$8,5,FALSE),'Fuel & Resister'!$B$3:$G$6,3,FALSE) -> 6.354 | AO10: 0 | AP10: 0
B11: nsr | C11: =VLOOKUP(B11,[1]SYS!$F$5:$G$359,2,FALSE) -> 39 | D11: Coal | E11: 2NOSHIR2 | F11: 能代火力発電所 | G11: 1 | H11: =W11/X11 -> 0.3 | I11: =X11/1000 -> 0.6 | J11: =1-Y11 -> 0.054 | K11: =Z11/1000 -> 2.49747 | L11: =AA11/1000 -> 2.08382 | M11: =(I11*10^6*L11/AJ11*AI11/10^6)*24*365/1000 -> 3.9029304 | N11: 6.145 | O11: 305 | P11: 0.05 | Q11: 8 | R11: 1 | S11: 1 | T11: 0 | U11: 0 | V11: 10 | W11: 180 | X11: 600 | Y11: 0.946 | Z11: 2497.47 | AA11: 2083.82 | AB11: 614.5 | AC11: 55 | AD11: =1/Z11*860 -> 0.34434848 | AE11: =1/AA11*860 -> 0.41270359 | AF11: =(L11-H11*K11)/(1-H11) -> 1.9065414 | AG11: =I11*(L11-AF11) -> 0.10636714 | AH11: =AB11/100 -> 6.145 | AI11: =HLOOKUP(HLOOKUP(G11,'THP2'!$B$4:$J$8,5,FALSE),'Fuel & Resister'!$B$3:$G$6,4,FALSE) -> 2.26424 | AJ11: =HLOOKUP(HLOOKUP(G11,'THP2'!$B$4:$J$8,5,FALSE),'Fuel & Resister'!$B$3:$G$6,3,FALSE) -> 6.354 | AO11: 0 | AP11: 0
A12: Nuclear | B12: nsr | C12: =VLOOKUP(B12,[1]SYS!$F$5:$G$359,2,FALSE) -> 39 | D12: Coal | E12: 2NOSHIR1 | F12: 能代火力発電所 | G12: 1 | H12: =W12/X12 -> 0.35 | I12: =X12/1000 -> 0.6 | J12: =1-Y12 -> 0.0559 | K12: =Z12/1000 -> 2.44598 | L12: =AA12/1000 -> 2.10201 | M12: =(I12*10^6*L12/AJ12*AI12/10^6)*24*365/1000 -> 3.9369997 | N12: 6.145 | O12: 305 | P12: 0.05 | Q12: 8 | R12: 1 | S12: 1 | T12: 0 | U12: 0 | V12: 11 | W12: 210 | X12: 600 | Y12: 0.9441 | Z12: 2445.98 | AA12: 2102.01 | AB12: 614.5 | AC12: 55 | AD12: =1/Z12*860 -> 0.35159731 | AE12: =1/AA12*860 -> 0.40913221 | AF12: =(L12-H12*K12)/(1-H12) -> 1.9167954 | AG12: =I12*(L12-AF12) -> 0.11112877 | AH12: =AB12/100 -> 6.145 | AI12: =HLOOKUP(HLOOKUP(G12,'THP2'!$B$4:$J$8,5,FALSE),'Fuel & Resister'!$B$3:$G$6,4,FALSE) -> 2.26424 | AJ12: =HLOOKUP(HLOOKUP(G12,'THP2'!$B$4:$J$8,5,FALSE),'Fuel & Resister'!$B$3:$G$6,3,FALSE) -> 6.354 | AO12: 0 | AP12: 0
A13: =ROWS(D447:D476) -> 30 | B13: sma | C13: =VLOOKUP(B13,[1]SYS!$F$5:$G$359,2,FALSE) -> 37 | D13: Coal | E13: 2SHINC2L | F13: 新地発電所 | G13: 1 | H13: =W13/X13 -> 0.164 | I13: =X13/1000 -> 1 | J13: =1-Y13 -> 0.0561 | K13: =Z13/1000 -> 2.9921 | L13: =AA13/1000 -> 2.11421 | M13: =(I13*10^6*L13/AJ13*AI13/10^6)*24*365/1000 -> 6.5997499 | N13: 15 | O13: 903 | P13: 0.05 | Q13: 8 | R13: 1 | S13: 1 | T13: 0 | U13: 0 | V13: 12 | W13: 164 | X13: 1000 | Y13: 0.9439 | Z13: 2992.1 | AA13: 2114.21 | AB13: 1500 | AC13: 55 | AD13: =1/Z13*860 -> 0.28742355 | AE13: =1/AA13*860 -> 0.40677132 | AF13: =(L13-H13*K13)/(1-H13) -> 1.9419923 | AG13: =I13*(L13-AF13) -> 0.17221766 | AH13: =AB13/100 -> 15 | AI13: =HLOOKUP(HLOOKUP(G13,'THP2'!$B$4:$J$8,5,FALSE),'Fuel & Resister'!$B$3:$G$6,4,FALSE) -> 2.26424 | AJ13: =HLOOKUP(HLOOKUP(G13,'THP2'!$B$4:$J$8,5,FALSE),'Fuel & Resister'!$B$3:$G$6,3,FALSE) -> 6.354 | AO13: 0 | AP13: 0
B14: sma | C14: =VLOOKUP(B14,[1]SYS!$F$5:$G$359,2,FALSE) -> 37 | D14: Coal | E14: 2SHINC1L | F14: 新地発電所 | G14: 1 | H14: =W14/X14 -> 0.164 | I14: =X14/1000 -> 1 | J14: =1-Y14 -> 0.0579 | K14: =Z14/1000 -> 3.00199 | L14: =AA14/1000 -> 2.1212 | M14: =(I14*10^6*L14/AJ14*AI14/10^6)*24*365/1000 -> 6.62157 | N14: 15 | O14: 403 | P14: 0.05 | Q14: 8 | R14: 1 | S14: 1 | T14: 0 | U14: 0 | V14: 13 | W14: 164 | X14: 1000 | Y14: 0.9421 | Z14: 3001.99 | AA14: 2121.2 | AB14: 1500 | AC14: 55 | AD14: =1/Z14*860 -> 0.28647664 | AE14: =1/AA14*860 -> 0.40543089 | AF14: =(L14-H14*K14)/(1-H14) -> 1.9484134 | AG14: =I14*(L14-AF14) -> 0.17278656 | AH14: =AB14/100 -> 15 | AI14: =HLOOKUP(HLOOKUP(G14,'THP2'!$B$4:$J$8,5,FALSE),'Fuel & Resister'!$B$3:$G$6,4,FALSE) -> 2.26424 | AJ14: =HLOOKUP(HLOOKUP(G14,'THP2'!$B$4:$J$8,5,FALSE),'Fuel & Resister'!$B$3:$G$6,3,FALSE) -> 6.354 | AO14: 0 | AP14: 0
B15: ism | C15: =VLOOKUP(B15,[1]SYS!$F$5:$G$359,2,FALSE) -> 46 | D15: Coal | E15: 2NS-HIB | F15: 石巻雲雀野発電所 | G15: 1 | H15: =W15/X15 -> 0.30201342 | I15: =X15/1000 -> 0.149 | J15: =1-Y15 -> 0.062 | K15: =Z15/1000 -> 2.57099 | L15: =AA15/1000 -> 2.14517 | M15: =(I15*10^6*L15/AJ15*AI15/10^6)*24*365/1000 -> 0.99776287 | N15: 1.192 | O15: 200 | P15: 0 | Q15: 8 | R15: 1 | S15: 1 | T15: 0 | U15: 1 | V15: 14 | W15: 45 | X15: 149 | Y15: 0.938 | Z15: 2570.99 | AA15: 2145.17 | AB15: 119.2 | AC15: 55 | AD15: =1/Z15*860 -> 0.3345015 | AE15: =1/AA15*860 -> 0.40090063 | AF15: =(L15-H15*K15)/(1-H15) -> 1.960921 | AG15: =I15*(L15-AF15) -> 0.027453107 | AH15: =AB15/100 -> 1.192 | AI15: =HLOOKUP(HLOOKUP(G15,'THP2'!$B$4:$J$8,5,FALSE),'Fuel & Resister'!$B$3:$G$6,4,FALSE) -> 2.26424 | AJ15: =HLOOKUP(HLOOKUP(G15,'THP2'!$B$4:$J$8,5,FALSE),'Fuel & Resister'!$B$3:$G$6,3,FALSE) -> 6.354 | AO15: 1 | AP15: 1
A16: Oil | B16: sdi | C16: =VLOOKUP(B16,[1]SYS!$F$5:$G$359,2,FALSE) -> 47 | D16: Coal | E16: 2ORIX-SM | F16: 相馬石炭・バイオマス発電所 | G16: 1 | H16: =W16/X16 -> 0.30097087 | I16: =X16/1000 -> 0.103 | J16: =1-Y16 -> 0 | K16: =Z16/1000 -> 2.60054 | L16: =AA16/1000 -> 2.16983 | M16: =(I16*10^6*L16/AJ16*AI16/10^6)*24*365/1000 -> 0.69765753 | N16: 0.824 | O16: 504 | P16: 0 | Q16: 8 | R16: 1 | S16: 1 | T16: 0 | U16: 1 | V16: 15 | W16: 31 | X16: 103 | Y16: 1 | Z16: 2600.54 | AA16: 2169.83 | AB16: 82.4 | AC16: 55 | AD16: =1/Z16*860 -> 0.33070055 | AE16: =1/AA16*860 -> 0.39634441 | AF16: =(L16-H16*K16)/(1-H16) -> 1.9843854 | AG16: =I16*(L16-AF16) -> 0.019100792 | AH16: =AB16/100 -> 0.824 | AI16: =HLOOKUP(HLOOKUP(G16,'THP2'!$B$4:$J$8,5,FALSE),'Fuel & Resister'!$B$3:$G$6,4,FALSE) -> 2.26424 | AJ16: =HLOOKUP(HLOOKUP(G16,'THP2'!$B$4:$J$8,5,FALSE),'Fuel & Resister'!$B$3:$G$6,3,FALSE) -> 6.354 | AO16: 1 | AP16: 1
A17: =ROWS(D477:D503) -> 27 | B17: sdi | C17: =VLOOKUP(B17,[1]SYS!$F$5:$G$359,2,FALSE) -> 47 | D17: Coal | E17: 2NTT-SM | G17: 1 | H17: =W17/X17 -> 0.3047619 | I17: =X17/1000 -> 0.105 | J17: =1-Y17 -> 0 | K17: =Z17/1000 -> 2.60054 | L17: =AA17/1000 -> 2.16983 | M17: =(I17*10^6*L17/AJ17*AI17/10^6)*24*365/1000 -> 0.71120428 | N17: 0.84 | O17: 1106 | P17: 0 | Q17: 8 | R17: 1 | S17: 1 | T17: 0 | U17: 1 | V17: 16 | W17: 32 | X17: 105 | Y17: 1 | Z17: 2600.54 | AA17: 2169.83 | AB17: 84 | AC17: 55 | AD17: =1/Z17*860 -> 0.33070055 | AE17: =1/AA17*860 -> 0.39634441 | AF17: =(L17-H17*K17)/(1-H17) -> 1.9810256 | AG17: =I17*(L17-AF17) -> 0.01982446 | AH17: =AB17/100 -> 0.84 | AI17: =HLOOKUP(HLOOKUP(G17,'THP2'!$B$4:$J$8,5,FALSE),'Fuel & Resister'!$B$3:$G$6,4,FALSE) -> 2.26424 | AJ17: =HLOOKUP(HLOOKUP(G17,'THP2'!$B$4:$J$8,5,FALSE),'Fuel & Resister'!$B$3:$G$6,3,FALSE) -> 6.354 | AO17: 1 | AP17: 1
B18: mzs | C18: =VLOOKUP(B18,[1]SYS!$F$5:$G$359,2,FALSE) -> 43 | D18: Coal | E18: 2IP-SEIT | F18: 日本製鉄釜石製鉄所 | G18: 1 | H18: =W18/X18 -> 0.30147059 | I18: =X18/1000 -> 0.136 | J18: =1-Y18 -> 0.064 | K18: =Z18/1000 -> 2.62159 | L18: =AA18/1000 -> 2.18739 | M18: =(I18*10^6*L18/AJ18*AI18/10^6)*24*365/1000 -> 0.9286338 | N18: 1.088 | O18: 903 | P18: 0 | Q18: 8 | R18: 1 | S18: 1 | T18: 0 | U18: 0 | V18: 17 | W18: 41 | X18: 136 | Y18: 0.936 | Z18: 2621.59 | AA18: 2187.39 | AB18: 108.8 | AC18: 55 | AD18: =1/Z18*860 -> 0.32804519 | AE18: =1/AA18*860 -> 0.39316263 | AF18: =(L18-H18*K18)/(1-H18) -> 1.9999984 | AG18: =I18*(L18-AF18) -> 0.025485255 | AH18: =AB18/100 -> 1.088 | AI18: =HLOOKUP(HLOOKUP(G18,'THP2'!$B$4:$J$8,5,FALSE),'Fuel & Resister'!$B$3:$G$6,4,FALSE) -> 2.26424 | AJ18: =HLOOKUP(HLOOKUP(G18,'THP2'!$B$4:$J$8,5,FALSE),'Fuel & Resister'!$B$3:$G$6,3,FALSE) -> 6.354 | AO18: 0 | AP18: 0
B19: ism | C19: =VLOOKUP(B19,[1]SYS!$F$5:$G$359,2,FALSE) -> 46 | D19: Coal | E19: 2NS-ISM | F19: 日本製紙石巻工場 | G19: 1 | H19: =W19/X19 -> 0.30181818 | I19: =X19/1000 -> 0.275 | J19: =1-Y19 -> 0.062 | K19: =Z19/1000 -> 2.62719 | L19: =AA19/1000 -> 2.19207 | M19: =(I19*10^6*L19/AJ19*AI19/10^6)*24*365/1000 -> 1.8817697 | N19: 2.4525 | O19: 1202 | P19: 0 | Q19: 8 | R19: 1 | S19: 1 | T19: 0 | U19: 1 | V19: 18 | W19: 83 | X19: 275 | Y19: 0.938 | Z19: 2627.19 | AA19: 2192.07 | AB19: 245.25 | AC19: 55 | AD19: =1/Z19*860 -> 0.32734595 | AE19: =1/AA19*860 -> 0.39232324 | AF19: =(L19-H19*K19)/(1-H19) -> 2.0039712 | AG19: =I19*(L19-AF19) -> 0.051727156 | AH19: =AB19/100 -> 2.4525 | AI19: =HLOOKUP(HLOOKUP(G19,'THP2'!$B$4:$J$8,5,FALSE),'Fuel & Resister'!$B$3:$G$6,4,FALSE) -> 2.26424 | AJ19: =HLOOKUP(HLOOKUP(G19,'THP2'!$B$4:$J$8,5,FALSE),'Fuel & Resister'!$B$3:$G$6,3,FALSE) -> 6.354 | AO19: 1 | AP19: 1
B20: hje | C20: =VLOOKUP(B20,[1]SYS!$F$5:$G$359,2,FALSE) -> 59 | D20: Coal | E20: 2ITOIGA1 | F20: 糸魚川発電所 | G20: 1 | H20: =W20/X20 -> 0.30201342 | I20: =X20/1000 -> 0.149 | J20: =1-Y20 -> 0.06 | K20: =Z20/1000 -> 2.6328 | L20: =AA20/1000 -> 2.19674 | M20: =(I20*10^6*L20/AJ20*AI20/10^6)*24*365/1000 -> 1.0217491 | N20: 1.192 | O20: 603 | P20: 0 | Q20: 8 | R20: 1 | S20: 1 | T20: 0 | U20: 1 | V20: 19 | W20: 45 | X20: 149 | Y20: 0.94 | Z20: 2632.8 | AA20: 2196.74 | AB20: 119.2 | AC20: 55 | AD20: =1/Z20*860 -> 0.32664844 | AE20: =1/AA20*860 -> 0.39148921 | AF20: =(L20-H20*K20)/(1-H20) -> 2.0080602 | AG20: =I20*(L20-AF20) -> 0.028113291 | AH20: =AB20/100 -> 1.192 | AI20: =HLOOKUP(HLOOKUP(G20,'THP2'!$B$4:$J$8,5,FALSE),'Fuel & Resister'!$B$3:$G$6,4,FALSE) -> 2.26424 | AJ20: =HLOOKUP(HLOOKUP(G20,'THP2'!$B$4:$J$8,5,FALSE),'Fuel & Resister'!$B$3:$G$6,3,FALSE) -> 6.354 | AO20: 1 | AP20: 1
B21: sdi | C21: =VLOOKUP(B21,[1]SYS!$F$5:$G$359,2,FALSE) -> 47 | D21: Coal | E21: 2SMT-ONH | F21: サミット小名浜エスパワー小名浜発電所 | G21: 1 | H21: =W21/X21 -> 0.30357143 | I21: =X21/1000 -> 0.056 | J21: =1-Y21 -> 0.4 | K21: =Z21/1000 -> 2.94489 | L21: =AA21/1000 -> 2.45714 | M21: =(I21*10^6*L21/AJ21*AI21/10^6)*24*365/1000 -> 0.42953374 | N21: 0.448 | O21: 601 | P21: 0 | Q21: 8 | R21: 1 | S21: 1 | T21: 0 | U21: 1 | V21: 20 | W21: 17 | X21: 56 | Y21: 0.6 | Z21: 2944.89 | AA21: 2457.14 | AB21: 44.8 | AC21: 55 | AD21: =1/Z21*860 -> 0.29203128 | AE21: =1/AA21*860 -> 0.35000041 | AF21: =(L21-H21*K21)/(1-H21) -> 2.244531 | AG21: =I21*(L21-AF21) -> 0.011906103 | AH21: =AB21/100 -> 0.448 | AI21: =HLOOKUP(HLOOKUP(G21,'THP2'!$B$4:$J$8,5,FALSE),'Fuel & Resister'!$B$3:$G$6,4,FALSE) -> 2.26424 | AJ21: =HLOOKUP(HLOOKUP(G21,'THP2'!$B$4:$J$8,5,FALSE),'Fuel & Resister'!$B$3:$G$6,3,FALSE) -> 6.354 | AO21: 1 | AP21: 1
B22: siw | C22: =VLOOKUP(B22,[1]SYS!$F$5:$G$359,2,FALSE) -> 64 | D22: Coal | E22: 3AD_COAL | G22: 1 | H22: =W22/X22 -> 0.3 | I22: =X22/1000 -> 1 | J22: =1-Y22 -> 0.062 | K22: =Z22/1000 -> 2.40035 | L22: =AA22/1000 -> 2.00279 | M22: =(I22*10^6*L22/AJ22*AI22/10^6)*24*365/1000 -> 6.2519395 | N22: 15 | O22: 403 | P22: 0.05 | Q22: 8 | R22: 1 | S22: 1 | T22: 0 | U22: 0 | V22: 21 | W22: 300 | X22: 1000 | Y22: 0.938 | Z22: 2400.35 | AA22: 2002.79 | AB22: 1500 | AC22: 55 | AD22: =1/Z22*860 -> 0.35828108 | AE22: =1/AA22*860 -> 0.42940099 | AF22: =(L22-H22*K22)/(1-H22) -> 1.8324071 | AG22: =I22*(L22-AF22) -> 0.17038286 | AH22: =AB22/100 -> 15 | AI22: =HLOOKUP(HLOOKUP(G22,'THP2'!$B$4:$J$8,5,FALSE),'Fuel & Resister'!$B$3:$G$6,4,FALSE) -> 2.26424 | AJ22: =HLOOKUP(HLOOKUP(G22,'THP2'!$B$4:$J$8,5,FALSE),'Fuel & Resister'!$B$3:$G$6,3,FALSE) -> 6.354 | AO22: 0 | AP22: 0
B23: siw | C23: =VLOOKUP(B23,[1]SYS!$F$5:$G$359,2,FALSE) -> 64 | D23: Coal | E23: 3AD_COAL | G23: 1 | H23: =W23/X23 -> 0.3 | I23: =X23/1000 -> 1 | J23: =1-Y23 -> 0.062 | K23: =Z23/1000 -> 2.40035 | L23: =AA23/1000 -> 2.00279 | M23: =(I23*10^6*L23/AJ23*AI23/10^6)*24*365/1000 -> 6.2519395 | N23: 15 | O23: 504 | P23: 0.05 | Q23: 8 | R23: 1 | S23: 1 | T23: 0 | U23: 0 | V23: 22 | W23: 300 | X23: 1000 | Y23: 0.938 | Z23: 2400.35 | AA23: 2002.79 | AB23: 1500 | AC23: 55 | AD23: =1/Z23*860 -> 0.35828108 | AE23: =1/AA23*860 -> 0.42940099 | AF23: =(L23-H23*K23)/(1-H23) -> 1.8324071 | AG23: =I23*(L23-AF23) -> 0.17038286 | AH23: =AB23/100 -> 15 | AI23: =HLOOKUP(HLOOKUP(G23,'THP2'!$B$4:$J$8,5,FALSE),'Fuel & Resister'!$B$3:$G$6,4,FALSE) -> 2.26424 | AJ23: =HLOOKUP(HLOOKUP(G23,'THP2'!$B$4:$J$8,5,FALSE),'Fuel & Resister'!$B$3:$G$6,3,FALSE) -> 6.354 | AO23: 0 | AP23: 0
B24: siw | C24: =VLOOKUP(B24,[1]SYS!$F$5:$G$359,2,FALSE) -> 64 | D24: Coal | E24: 3AD_COAL | G24: 1 | H24: =W24/X24 -> 0.3 | I24: =X24/1000 -> 1 | J24: =1-Y24 -> 0.062 | K24: =Z24/1000 -> 2.40035 | L24: =AA24/1000 -> 2.00279 | M24: =(I24*10^6*L24/AJ24*AI24/10^6)*24*365/1000 -> 6.2519395 | N24: 15 | O24: 403 | P24: 0.05 | Q24: 8 | R24: 1 | S24: 1 | T24: 0 | U24: 0 | V24: 23 | W24: 300 | X24: 1000 | Y24: 0.938 | Z24: 2400.35 | AA24: 2002.79 | AB24: 1500 | AC24: 55 | AD24: =1/Z24*860 -> 0.35828108 | AE24: =1/AA24*860 -> 0.42940099 | AF24: =(L24-H24*K24)/(1-H24) -> 1.8324071 | AG24: =I24*(L24-AF24) -> 0.17038286 | AH24: =AB24/100 -> 15 | AI24: =HLOOKUP(HLOOKUP(G24,'THP2'!$B$4:$J$8,5,FALSE),'Fuel & Resister'!$B$3:$G$6,4,FALSE) -> 2.26424 | AJ24: =HLOOKUP(HLOOKUP(G24,'THP2'!$B$4:$J$8,5,FALSE),'Fuel & Resister'!$B$3:$G$6,3,FALSE) -> 6.354 | AO24: 0 | AP24: 0
B25: siw | C25: =VLOOKUP(B25,[1]SYS!$F$5:$G$359,2,FALSE) -> 64 | D25: Coal | E25: 3AD_COAL | G25: 1 | H25: =W25/X25 -> 0.3 | I25: =X25/1000 -> 1 | J25: =1-Y25 -> 0.062 | K25: =Z25/1000 -> 2.40035 | L25: =AA25/1000 -> 2.00279 | M25: =(I25*10^6*L25/AJ25*AI25/10^6)*24*365/1000 -> 6.2519395 | N25: 15 | O25: 504 | P25: 0.05 | Q25: 8 | R25: 1 | S25: 1 | T25: 0 | U25: 0 | V25: 24 | W25: 300 | X25: 1000 | Y25: 0.938 | Z25: 2400.35 | AA25: 2002.79 | AB25: 1500 | AC25: 55 | AD25: =1/Z25*860 -> 0.35828108 | AE25: =1/AA25*860 -> 0.42940099 | AF25: =(L25-H25*K25)/(1-H25) -> 1.8324071 | AG25: =I25*(L25-AF25) -> 0.17038286 | AH25: =AB25/100 -> 15 | AI25: =HLOOKUP(HLOOKUP(G25,'THP2'!$B$4:$J$8,5,FALSE),'Fuel & Resister'!$B$3:$G$6,4,FALSE) -> 2.26424 | AJ25: =HLOOKUP(HLOOKUP(G25,'THP2'!$B$4:$J$8,5,FALSE),'Fuel & Resister'!$B$3:$G$6,3,FALSE) -> 6.354 | AO25: 0 | AP25: 0
B26: siw | C26: =VLOOKUP(B26,[1]SYS!$F$5:$G$359,2,FALSE) -> 64 | D26: Coal | E26: 3AD_COAL | G26: 1 | H26: =W26/X26 -> 0.3 | I26: =X26/1000 -> 1 | J26: =1-Y26 -> 0.062 | K26: =Z26/1000 -> 2.40035 | L26: =AA26/1000 -> 2.00279 | M26: =(I26*10^6*L26/AJ26*AI26/10^6)*24*365/1000 -> 6.2519395 | N26: 15 | O26: 403 | P26: 0.05 | Q26: 8 | R26: 1 | S26: 1 | T26: 0 | U26: 0 | V26: 25 | W26: 300 | X26: 1000 | Y26: 0.938 | Z26: 2400.35 | AA26: 2002.79 | AB26: 1500 | AC26: 55 | AD26: =1/Z26*860 -> 0.35828108 | AE26: =1/AA26*860 -> 0.42940099 | AF26: =(L26-H26*K26)/(1-H26) -> 1.8324071 | AG26: =I26*(L26-AF26) -> 0.17038286 | AH26: =AB26/100 -> 15 | AI26: =HLOOKUP(HLOOKUP(G26,'THP2'!$B$4:$J$8,5,FALSE),'Fuel & Resister'!$B$3:$G$6,4,FALSE) -> 2.26424 | AJ26: =HLOOKUP(HLOOKUP(G26,'THP2'!$B$4:$J$8,5,FALSE),'Fuel & Resister'!$B$3:$G$6,3,FALSE) -> 6.354 | AO26: 0 | AP26: 0
B27: siw | C27: =VLOOKUP(B27,[1]SYS!$F$5:$G$359,2,FALSE) -> 64 | D27: Coal | E27: 3AD_COAL | G27: 1 | H27: =W27/X27 -> 0.3 | I27: =X27/1000 -> 1 | J27: =1-Y27 -> 0.062 | K27: =Z27/1000 -> 2.40035 | L27: =AA27/1000 -> 2.00279 | M27: =(I27*10^6*L27/AJ27*AI27/10^6)*24*365/1000 -> 6.2519395 | N27: 15 | O27: 504 | P27: 0.05 | Q27: 8 | R27: 1 | S27: 1 | T27: 0 | U27: 0 | V27: 26 | W27: 300 | X27: 1000 | Y27: 0.938 | Z27: 2400.35 | AA27: 2002.79 | AB27: 1500 | AC27: 55 | AD27: =1/Z27*860 -> 0.35828108 | AE27: =1/AA27*860 -> 0.42940099 | AF27: =(L27-H27*K27)/(1-H27) -> 1.8324071 | AG27: =I27*(L27-AF27) -> 0.17038286 | AH27: =AB27/100 -> 15 | AI27: =HLOOKUP(HLOOKUP(G27,'THP2'!$B$4:$J$8,5,FALSE),'Fuel & Resister'!$B$3:$G$6,4,FALSE) -> 2.26424 | AJ27: =HLOOKUP(HLOOKUP(G27,'THP2'!$B$4:$J$8,5,FALSE),'Fuel & Resister'!$B$3:$G$6,3,FALSE) -> 6.354 | AO27: 0 | AP27: 0
B28: siw | C28: =VLOOKUP(B28,[1]SYS!$F$5:$G$359,2,FALSE) -> 64 | D28: Coal | E28: 3AD_COAL | G28: 1 | H28: =W28/X28 -> 0.3 | I28: =X28/1000 -> 1 | J28: =1-Y28 -> 0.062 | K28: =Z28/1000 -> 2.40035 | L28: =AA28/1000 -> 2.00279 | M28: =(I28*10^6*L28/AJ28*AI28/10^6)*24*365/1000 -> 6.2519395 | N28: 15 | O28: 403 | P28: 0.05 | Q28: 8 | R28: 1 | S28: 1 | T28: 0 | U28: 0 | V28: 27 | W28: 300 | X28: 1000 | Y28: 0.938 | Z28: 2400.35 | AA28: 2002.79 | AB28: 1500 | AC28: 55 | AD28: =1/Z28*860 -> 0.35828108 | AE28: =1/AA28*860 -> 0.42940099 | AF28: =(L28-H28*K28)/(1-H28) -> 1.8324071 | AG28: =I28*(L28-AF28) -> 0.17038286 | AH28: =AB28/100 -> 15 | AI28: =HLOOKUP(HLOOKUP(G28,'THP2'!$B$4:$J$8,5,FALSE),'Fuel & Resister'!$B$3:$G$6,4,FALSE) -> 2.26424 | AJ28: =HLOOKUP(HLOOKUP(G28,'THP2'!$B$4:$J$8,5,FALSE),'Fuel & Resister'!$B$3:$G$6,3,FALSE) -> 6.354 | AO28: 0 | AP28: 0
B29: siw | C29: =VLOOKUP(B29,[1]SYS!$F$5:$G$359,2,FALSE) -> 64 | D29: Coal | E29: 3AD_COAL | G29: 1 | H29: =W29/X29 -> 0.3 | I29: =X29/1000 -> 1 | J29: =1-Y29 -> 0.062 | K29: =Z29/1000 -> 2.40035 | L29: =AA29/1000 -> 2.00279 | M29: =(I29*10^6*L29/AJ29*AI29/10^6)*24*365/1000 -> 6.2519395 | N29: 15 | O29: 403 | P29: 0.05 | Q29: 8 | R29: 1 | S29: 1 | T29: 0 | U29: 0 | V29: 28 | W29: 300 | X29: 1000 | Y29: 0.938 | Z29: 2400.35 | AA29: 2002.79 | AB29: 1500 | AC29: 55 | AD29: =1/Z29*860 -> 0.35828108 | AE29: =1/AA29*860 -> 0.42940099 | AF29: =(L29-H29*K29)/(1-H29) -> 1.8324071 | AG29: =I29*(L29-AF29) -> 0.17038286 | AH29: =AB29/100 -> 15 | AI29: =HLOOKUP(HLOOKUP(G29,'THP2'!$B$4:$J$8,5,FALSE),'Fuel & Resister'!$B$3:$G$6,4,FALSE) -> 2.26424 | AJ29: =HLOOKUP(HLOOKUP(G29,'THP2'!$B$4:$J$8,5,FALSE),'Fuel & Resister'!$B$3:$G$6,3,FALSE) -> 6.354 | AO29: 0 | AP29: 0
B30: siw | C30: =VLOOKUP(B30,[1]SYS!$F$5:$G$359,2,FALSE) -> 64 | D30: Coal | E30: 3AD_COAL | G30: 1 | H30: =W30/X30 -> 0.3 | I30: =X30/1000 -> 1 | J30: =1-Y30 -> 0.062 | K30: =Z30/1000 -> 2.40035 | L30: =AA30/1000 -> 2.00279 | M30: =(I30*10^6*L30/AJ30*AI30/10^6)*24*365/1000 -> 6.2519395 | N30: 15 | O30: 403 | P30: 0.05 | Q30: 8 | R30: 1 | S30: 1 | T30: 0 | U30: 0 | V30: 29 | W30: 300 | X30: 1000 | Y30: 0.938 | Z30: 2400.35 | AA30: 2002.79 | AB30: 1500 | AC30: 55 | AD30: =1/Z30*860 -> 0.35828108 | AE30: =1/AA30*860 -> 0.42940099 | AF30: =(L30-H30*K30)/(1-H30) -> 1.8324071 | AG30: =I30*(L30-AF30) -> 0.17038286 | AH30: =AB30/100 -> 15 | AI30: =HLOOKUP(HLOOKUP(G30,'THP2'!$B$4:$J$8,5,FALSE),'Fuel & Resister'!$B$3:$G$6,4,FALSE) -> 2.26424 | AJ30: =HLOOKUP(HLOOKUP(G30,'THP2'!$B$4:$J$8,5,FALSE),'Fuel & Resister'!$B$3:$G$6,3,FALSE) -> 6.354 | AO30: 0 | AP30: 0
B31: siw | C31: =VLOOKUP(B31,[1]SYS!$F$5:$G$359,2,FALSE) -> 64 | D31: Coal | E31: 3AD_COAL | G31: 1 | H31: =W31/X31 -> 0.3 | I31: =X31/1000 -> 1 | J31: =1-Y31 -> 0.062 | K31: =Z31/1000 -> 2.40035 | L31: =AA31/1000 -> 2.00279 | M31: =(I31*10^6*L31/AJ31*AI31/10^6)*24*365/1000 -> 6.2519395 | N31: 15 | O31: 403 | P31: 0.05 | Q31: 8 | R31: 1 | S31: 1 | T31: 0 | U31: 0 | V31: 30 | W31: 300 | X31: 1000 | Y31: 0.938 | Z31: 2400.35 | AA31: 2002.79 | AB31: 1500 | AC31: 55 | AD31: =1/Z31*860 -> 0.35828108 | AE31: =1/AA31*860 -> 0.42940099 | AF31: =(L31-H31*K31)/(1-H31) -> 1.8324071 | AG31: =I31*(L31-AF31) -> 0.17038286 | AH31: =AB31/100 -> 15 | AI31: =HLOOKUP(HLOOKUP(G31,'THP2'!$B$4:$J$8,5,FALSE),'Fuel & Resister'!$B$3:$G$6,4,FALSE) -> 2.26424 | AJ31: =HLOOKUP(HLOOKUP(G31,'THP2'!$B$4:$J$8,5,FALSE),'Fuel & Resister'!$B$3:$G$6,3,FALSE) -> 6.354 | AO31: 0 | AP31: 0
B32: siw | C32: =VLOOKUP(B32,[1]SYS!$F$5:$G$359,2,FALSE) -> 64 | D32: Coal | E32: 3AD_COAL | G32: 1 | H32: =W32/X32 -> 0.3 | I32: =X32/1000 -> 1 | J32: =1-Y32 -> 0.062 | K32: =Z32/1000 -> 2.40035 | L32: =AA32/1000 -> 2.00279 | M32: =(I32*10^6*L32/AJ32*AI32/10^6)*24*365/1000 -> 6.2519395 | N32: 15 | O32: 204 | P32: 0.05 | Q32: 8 | R32: 1 | S32: 1 | T32: 0 | U32: 0 | V32: 31 | W32: 300 | X32: 1000 | Y32: 0.938 | Z32: 2400.35 | AA32: 2002.79 | AB32: 1500 | AC32: 55 | AD32: =1/Z32*860 -> 0.35828108 | AE32: =1/AA32*860 -> 0.42940099 | AF32: =(L32-H32*K32)/(1-H32) -> 1.8324071 | AG32: =I32*(L32-AF32) -> 0.17038286 | AH32: =AB32/100 -> 15 | AI32: =HLOOKUP(HLOOKUP(G32,'THP2'!$B$4:$J$8,5,FALSE),'Fuel & Resister'!$B$3:$G$6,4,FALSE) -> 2.26424 | AJ32: =HLOOKUP(HLOOKUP(G32,'THP2'!$B$4:$J$8,5,FALSE),'Fuel & Resister'!$B$3:$G$6,3,FALSE) -> 6.354 | AO32: 0 | AP32: 0
B33: siw | C33: =VLOOKUP(B33,[1]SYS!$F$5:$G$359,2,FALSE) -> 64 | D33: Coal | E33: 3AD_COAL | G33: 1 | H33: =W33/X33 -> 0.3 | I33: =X33/1000 -> 1 | J33: =1-Y33 -> 0.062 | K33: =Z33/1000 -> 2.40035 | L33: =AA33/1000 -> 2.00279 | M33: =(I33*10^6*L33/AJ33*AI33/10^6)*24*365/1000 -> 6.2519395 | N33: 15 | O33: 1103 | P33: 0.05 | Q33: 8 | R33: 1 | S33: 1 | T33: 0 | U33: 0 | V33: 32 | W33: 300 | X33: 1000 | Y33: 0.938 | Z33: 2400.35 | AA33: 2002.79 | AB33: 1500 | AC33: 55 | AD33: =1/Z33*860 -> 0.35828108 | AE33: =1/AA33*860 -> 0.42940099 | AF33: =(L33-H33*K33)/(1-H33) -> 1.8324071 | AG33: =I33*(L33-AF33) -> 0.17038286 | AH33: =AB33/100 -> 15 | AI33: =HLOOKUP(HLOOKUP(G33,'THP2'!$B$4:$J$8,5,FALSE),'Fuel & Resister'!$B$3:$G$6,4,FALSE) -> 2.26424 | AJ33: =HLOOKUP(HLOOKUP(G33,'THP2'!$B$4:$J$8,5,FALSE),'Fuel & Resister'!$B$3:$G$6,3,FALSE) -> 6.354 | AO33: 0 | AP33: 0
... B36: siw | C36: =VLOOKUP(B36,[1]SYS!$F$5:$G$359,2,FALSE) -> 64 | D36: Coal | E36: 3AD_COAL | G36: 1 | H36: =W36/X36 -> 0.3 | I36: =X36/1000 -> 1 | J36: =1-Y36 -> 0.062 | K36: =Z36/1000 -> 2.40035 | L36: =AA36/1000 -> 2.00279 | M36: =(I36*10^6*L36/AJ36*AI36/10^6)*24*365/1000 -> 6.2519395 | N36: 15 | O36: 401 | P36: 0.05 | Q36: 8 | R36: 1 | S36: 1 | T36: 0 | U36: 0 | V36: 35 | W36: 300 | X36: 1000 | Y36: 0.938 | Z36: 2400.35 | AA36: 2002.79 | AB36: 1500 | AC36: 55 | AD36: =1/Z36*860 -> 0.35828108 | AE36: =1/AA36*860 -> 0.42940099 | AF36: =(L36-H36*K36)/(1-H36) -> 1.8324071 | AG36: =I36*(L36-AF36) -> 0.17038286 | AH36: =AB36/100 -> 15 | AI36: =HLOOKUP(HLOOKUP(G36,'THP2'!$B$4:$J$8,5,FALSE),'Fuel & Resister'!$B$3:$G$6,4,FALSE) -> 2.26424 | AJ36: =HLOOKUP(HLOOKUP(G36,'THP2'!$B$4:$J$8,5,FALSE),'Fuel & Resister'!$B$3:$G$6,3,FALSE) -> 6.354 | AO36: 0 | AP36: 0
B37: siw | C37: =VLOOKUP(B37,[1]SYS!$F$5:$G$359,2,FALSE) -> 64 | D37: Coal | E37: 3NAKO10L | F37: 勿来発電所 | G37: 1 | H37: =W37/X37 -> 0.4 | I37: =X37/1000 -> 0.25 | J37: =1-Y37 -> 0.125 | K37: =Z37/1000 -> 2.4389 | L37: =AA37/1000 -> 1.86957 | M37: =(I37*10^6*L37/AJ37*AI37/10^6)*24*365/1000 -> 1.4590195 | N37: 2.1683 | O37: 302 | P37: 0.05 | Q37: 8 | R37: 1 | S37: 1 | T37: 0 | U37: 1 | V37: 36 | W37: 100 | X37: 250 | Y37: 0.875 | Z37: 2438.9 | AA37: 1869.57 | AB37: 216.83 | AC37: 55 | AD37: =1/Z37*860 -> 0.35261798 | AE37: =1/AA37*860 -> 0.45999882 | AF37: =(L37-H37*K37)/(1-H37) -> 1.4900167 | AG37: =I37*(L37-AF37) -> 0.094888333 | AH37: =AB37/100 -> 2.1683 | AI37: =HLOOKUP(HLOOKUP(G37,'THP2'!$B$4:$J$8,5,FALSE),'Fuel & Resister'!$B$3:$G$6,4,FALSE) -> 2.26424 | AJ37: =HLOOKUP(HLOOKUP(G37,'THP2'!$B$4:$J$8,5,FALSE),'Fuel & Resister'!$B$3:$G$6,3,FALSE) -> 6.354 | AO37: 1 | AP37: 1
B38: siw | C38: =VLOOKUP(B38,[1]SYS!$F$5:$G$359,2,FALSE) -> 64 | D38: Coal | E38: 3IGCC501 | F38: 勿来発電所 | G38: 1 | H38: =W38/X38 -> 0.4 | I38: =X38/1000 -> 0.54 | J38: =1-Y38 -> 0.125 | K38: =Z38/1000 -> 2.46029 | L38: =AA38/1000 -> 1.88596 | M38: =(I38*10^6*L38/AJ38*AI38/10^6)*24*365/1000 -> 3.1791103 | N38: 5.464 | O38: 403 | P38: 0.05 | Q38: 8 | R38: 1 | S38: 1 | T38: 0 | U38: 1 | V38: 37 | W38: 216 | X38: 540 | Y38: 0.875 | Z38: 2460.29 | AA38: 1885.96 | AB38: 546.4 | AC38: 55 | AD38: =1/Z38*860 -> 0.34955229 | AE38: =1/AA38*860 -> 0.45600119 | AF38: =(L38-H38*K38)/(1-H38) -> 1.5030733 | AG38: =I38*(L38-AF38) -> 0.2067588 | AH38: =AB38/100 -> 5.464 | AI38: =HLOOKUP(HLOOKUP(G38,'THP2'!$B$4:$J$8,5,FALSE),'Fuel & Resister'!$B$3:$G$6,4,FALSE) -> 2.26424 | AJ38: =HLOOKUP(HLOOKUP(G38,'THP2'!$B$4:$J$8,5,FALSE),'Fuel & Resister'!$B$3:$G$6,3,FALSE) -> 6.354 | AO38: 1 | AP38: 1
B39: siw | C39: =VLOOKUP(B39,[1]SYS!$F$5:$G$359,2,FALSE) -> 64 | D39: Coal | E39: 3IGCC502 | F39: 勿来発電所 | G39: 1 | H39: =W39/X39 -> 0.4 | I39: =X39/1000 -> 0.54 | J39: =1-Y39 -> 0.125 | K39: =Z39/1000 -> 2.46029 | L39: =AA39/1000 -> 1.88596 | M39: =(I39*10^6*L39/AJ39*AI39/10^6)*24*365/1000 -> 3.1791103 | N39: 5.464 | O39: 903 | P39: 0.05 | Q39: 8 | R39: 1 | S39: 1 | T39: 0 | U39: 1 | V39: 38 | W39: 216 | X39: 540 | Y39: 0.875 | Z39: 2460.29 | AA39: 1885.96 | AB39: 546.4 | AC39: 55 | AD39: =1/Z39*860 -> 0.34955229 | AE39: =1/AA39*860 -> 0.45600119 | AF39: =(L39-H39*K39)/(1-H39) -> 1.5030733 | AG39: =I39*(L39-AF39) -> 0.2067588 | AH39: =AB39/100 -> 5.464 | AI39: =HLOOKUP(HLOOKUP(G39,'THP2'!$B$4:$J$8,5,FALSE),'Fuel & Resister'!$B$3:$G$6,4,FALSE) -> 2.26424 | AJ39: =HLOOKUP(HLOOKUP(G39,'THP2'!$B$4:$J$8,5,FALSE),'Fuel & Resister'!$B$3:$G$6,3,FALSE) -> 6.354 | AO39: 1 | AP39: 1
B40: siw | C40: =VLOOKUP(B40,[1]SYS!$F$5:$G$359,2,FALSE) -> 64 | D40: Coal | E40: 3HITA_G | F40: 日本製鉄鹿島火力発電所 | G40: 1 | H40: =W40/X40 -> 0.3 | I40: =X40/1000 -> 0.65 | J40: =1-Y40 -> 0.062 | K40: =Z40/1000 -> 2.397 | L40: =AA40/1000 -> 2 | M40: =(I40*10^6*L40/AJ40*AI40/10^6)*24*365/1000 -> 4.0580996 | N40: 6.7125 | O40: 504 | P40: 0.05 | Q40: 8 | R40: 1 | S40: 1 | T40: 0 | U40: 1 | V40: 39 | W40: 195 | X40: 650 | Y40: 0.938 | Z40: 2397 | AA40: 2000 | AB40: 671.25 | AC40: 55 | AD40: =1/Z40*860 -> 0.35878181 | AE40: =1/AA40*860 -> 0.43 | AF40: =(L40-H40*K40)/(1-H40) -> 1.8298571 | AG40: =I40*(L40-AF40) -> 0.11059286 | AH40: =AB40/100 -> 6.7125 | AI40: =HLOOKUP(HLOOKUP(G40,'THP2'!$B$4:$J$8,5,FALSE),'Fuel & Resister'!$B$3:$G$6,4,FALSE) -> 2.26424 | AJ40: =HLOOKUP(HLOOKUP(G40,'THP2'!$B$4:$J$8,5,FALSE),'Fuel & Resister'!$B$3:$G$6,3,FALSE) -> 6.354 | AO40: 1 | AP40: 1
B41: sky | C41: =VLOOKUP(B41,[1]SYS!$F$5:$G$359,2,FALSE) -> 75 | D41: Coal | E41: 3SODEG1 | F41: 千葉袖ケ浦パワー | G41: 1 | H41: =W41/X41 -> 0.3 | I41: =X41/1000 -> 1 | J41: =1-Y41 -> 0.02 | K41: =Z41/1000 -> 2.397 | L41: =AA41/1000 -> 2 | M41: =(I41*10^6*L41/AJ41*AI41/10^6)*24*365/1000 -> 6.2432302 | N41: 15 | O41: 403 | P41: 0.05 | Q41: 8 | R41: 1 | S41: 1 | T41: 0 | U41: 1 | V41: 40 | W41: 300 | X41: 1000 | Y41: 0.98 | Z41: 2397 | AA41: 2000 | AB41: 1500 | AC41: 55 | AD41: =1/Z41*860 -> 0.35878181 | AE41: =1/AA41*860 -> 0.43 | AF41: =(L41-H41*K41)/(1-H41) -> 1.8298571 | AG41: =I41*(L41-AF41) -> 0.17014286 | AH41: =AB41/100 -> 15 | AI41: =HLOOKUP(HLOOKUP(G41,'THP2'!$B$4:$J$8,5,FALSE),'Fuel & Resister'!$B$3:$G$6,4,FALSE) -> 2.26424 | AJ41: =HLOOKUP(HLOOKUP(G41,'THP2'!$B$4:$J$8,5,FALSE),'Fuel & Resister'!$B$3:$G$6,3,FALSE) -> 6.354 | AO41: 1 | AP41: 1
B42: sky | C42: =VLOOKUP(B42,[1]SYS!$F$5:$G$359,2,FALSE) -> 75 | D42: Coal | E42: 3SODEG2 | F42: 千葉袖ケ浦パワー | G42: 1 | H42: =W42/X42 -> 0.3 | I42: =X42/1000 -> 1 | J42: =1-Y42 -> 0.02 | K42: =Z42/1000 -> 2.397 | L42: =AA42/1000 -> 2 | M42: =(I42*10^6*L42/AJ42*AI42/10^6)*24*365/1000 -> 6.2432302 | N42: 15 | O42: 403 | P42: 0.05 | Q42: 8 | R42: 1 | S42: 1 | T42: 0 | U42: 1 | V42: 41 | W42: 300 | X42: 1000 | Y42: 0.98 | Z42: 2397 | AA42: 2000 | AB42: 1500 | AC42: 55 | AD42: =1/Z42*860 -> 0.35878181 | AE42: =1/AA42*860 -> 0.43 | AF42: =(L42-H42*K42)/(1-H42) -> 1.8298571 | AG42: =I42*(L42-AF42) -> 0.17014286 | AH42: =AB42/100 -> 15 | AI42: =HLOOKUP(HLOOKUP(G42,'THP2'!$B$4:$J$8,5,FALSE),'Fuel & Resister'!$B$3:$G$6,4,FALSE) -> 2.26424 | AJ42: =HLOOKUP(HLOOKUP(G42,'THP2'!$B$4:$J$8,5,FALSE),'Fuel & Resister'!$B$3:$G$6,3,FALSE) -> 6.354 | AO42: 1 | AP42: 1
...

Sheet THP2
A3: =COLUMNS(PUC) -> 9 | B3: =VLOOKUP(B4,$C$21:$D$25,2,FALSE) -> Nuclear | C3: =VLOOKUP(C4,$C$21:$D$25,2,FALSE) -> Coal | D3: =VLOOKUP(D4,$C$21:$D$25,2,FALSE) -> LNG ST | E3: =VLOOKUP(E4,$C$21:$D$25,2,FALSE) -> LNG GCC | F3: =VLOOKUP(F4,$C$21:$D$25,2,FALSE) -> Oil | G3: NH3_20% | H3: NH3_50% | I3: H2_30% | J3: H2_100%
A4: Plant Type | B4: 0 | C4: 1 | D4: 2 | E4: 3 | F4: 4 | G4: 5 | H4: 6 | I4: 7 | J4: 8
A5: Unit Construction Cost [kYen/kW] | B5: 400 | C5: 270 | D5: 170 | E5: 100 | F5: 145 | G5: 270 | H5: 270 | I5: 100 | J5: 100
A6: Life Time [year] | B6: 40 | C6: 40 | D6: 40 | E6: 40 | F6: 40 | G6: 40 | H6: 40 | I6: 40 | J6: 40
A7: Annual O&M Cost Rate | B7: 0.04 | C7: 0.048 | D7: 0.036 | E7: 0.036 | F7: 0.039 | G7: 0.048 | H7: 0.048 | I7: 0.036 | J7: 0.036
A8: Fuel Type | B8: 3 | C8: 2 | D8: 0 | E8: 0 | F8: 1 | G8: 4 | H8: 5 | I8: 0 | J8: 0
A9: R in Boiler (0:No, 1:Yes) | B9: 0 | C9: 1 | D9: 1 | E9: 0 | F9: 1 | G9: 1 | H9: 1 | I9: 0 | J9: 0
A10: R in Condenser (0:No, 1:Yes) | B10: 1 | C10: 1 | D10: 1 | E10: 1 | F10: 1 | G10: 1 | H10: 1 | I10: 1 | J10: 1
A11: Minimun Stut-down Time [hour] | B11: 12 | C11: 8 | D11: 8 | E11: 4 | F11: 8 | G11: 8 | H11: 8 | I11: 4 | J11: 4 | M11: 12 | N11: 8 | O11: 8 | P11: 4 | Q11: 8
A12: Minimun Operation Time [hour] | B12: 12 | C12: 4 | D12: 2 | E12: 1 | F12: 2 | G12: 4 | H12: 4 | I12: 1 | J12: 1 | M12: 12 | N12: 4 | O12: 2 | P12: 1 | Q12: 2
A13: Load Following Capability | B13: 0 | C13: 1 | D13: 1 | E13: 1 | F13: 1 | G13: 1 | H13: 1 | I13: 1 | J13: 1
A14: Annual Maintenance Period [day] | B14: 60 | C14: 55 | D14: 46 | E14: 36 | F14: 46 | G14: 55 | H14: 55 | I14: 36 | J14: 36
A15: Carbon Capture Construction Cost [kyen/(t-CO2/year)] | B15: 0 | C15: =116*1000/(24*365) -> 13.242009 | D15: =116*1000/(24*365) -> 13.242009 | E15: =116*1000/(24*365) -> 13.242009 | F15: =116*1000/(24*365) -> 13.242009 | G15: =116*1000/(24*365) -> 13.242009 | H15: =116*1000/(24*365) -> 13.242009 | I15: =116*1000/(24*365) -> 13.242009 | J15: =116*1000/(24*365) -> 13.242009 | M15: CCS 諸元 | N15: https://www.meti.go.jp/press/2020/05/20200515002/20200515002-1.pdf
A16: Carbon Capture Life Time [year] | B16: 0 | C16: 25 | D16: 25 | E16: 25 | F16: 25 | G16: 25 | H16: 25 | I16: 25 | J16: 25 | N16: https://criepi.denken.or.jp/hokokusho/pb/reportDownload?reportNoUkCode=M20002&tenpuTypeCode=30&seqNo=1&reportId=9011
A17: Electricity Consumption with CCS [kWh/t] | B17: 0 | C17: 106 | D17: 120 | E17: 120 | F17: 106 | G17: 106 | H17: 106 | I17: 120 | J17: 120
C21: 0 | D21: Nuclear
C22: 1 | D22: Coal
C23: 2 | D23: LNG ST
C24: 3 | D24: LNG GCC
C25: 4 | D25: Oil

Sheet Fuel & Resister
B1: 6
A2: Type | B2: Natural Gas | C2: Oil | D2: Coal | E2: Nuclear | F2: Coal-NH3_20% | G2: Coal-NH3_50% | I2: Cost of Resistance in Boiler [kYen/kW/year] | J2: 0.3 | M2: NH3 Fuel Cost(yen/kg)
A3: Plant Type Number | B3: 0 | C3: 1 | D3: 2 | E3: 3 | F3: 4 | G3: 5 | I3: Cost of Resistance in Condenser [kYen/kW/year] | J3: 0.2 | M3: =317*120/1000 -> 38.04
A4: Fuel Cost [Yen/specific unit] | B4: =B9*B5*1000 -> 65.813076 | C4: =C9*C5*1000 -> 68.874956 | D4: =D9*D5*1000 -> 11.971832 | E4: 1.7 | F4: =$M$3*0.29/1.29+$D$4*1/1.29 -> 17.832118 | G4: =$M$3*26.1/48.6+$D$4*22.5/48.6 -> 25.971404 | O4: cal | P4: J | S4: Btu | T4: J | W4: kWh | X4: J
A5: Heat Content[Mcal/specific unit] | B5: 13.019 | C5: 9.842 | D5: 6.354 | E5: 2.47839 | F5: =$D$5*1/1.29+22.5/($T$8*1000)*$U$8*0.29/1.29 -> 6.1345057 | G5: =$D$5*22.5/48.6+22.5/($T$8*1000)*$U$8*26.1/48.6 -> 5.8296526 | M5: NH3 Fuel Cost(yen/GWh) | O5: 1 | P5: 4.184 | S5: 1 | T5: 1055.06 | W5: 1 | X5: 3600000
A6: CO2 Intensity[kg-CO2/specific unit] | B6: 2.7360667 | C6: 2.88904 | D6: 2.26424 | E6: 0 | F6: =$D$6*100/129 -> 1.7552248 | G6: =$D$6*22.5/48.6 -> 1.0482593 | I6: =22.5/($T$8*1000)*$U$8 -> 5.377629 | M6: =M3/22.5*X5 -> 6086400
A7: Specific Unit | B7: kg | C7: liter | D7: kg | E7: kWh | F7: kg | G7: kg | S7: MMBtu | T7: GJ | U7: Mcal | W7: ktoe | X7: Mcal
I8: =HLOOKUP(B2,B2:E3,2,FALSE) -> 0 | O8: toe | P8: J | Q8: cal | S8: 1 | T8: 1.05506 | U8: 252.16539 | W8: 1 | X8: 1.00382.E+07
A9: Cost [kYen/Mcal] | B9: 0.005055156 | C9: 0.006998065 | D9: 0.001884141 | G9: =G4/1000/G5 -> 0.0044550517 | O9: 1 | P9: 42000000000 | Q9: 10040000000
B11: =B4/B5 -> 5.055156 | D11: =D4/D5 -> 1.884141 | F11: =22.5/(26.1+22.5)*2.26424/G5 -> 0.17981505 | G11: =G4/G5 -> 4.4550517
F12: =B6/B5 -> 0.21015951 | G12: =B4/B5 -> 5.055156 | U12: =7*3.195/3 -> 7.455
F13: =(6.2897-4.4550516)/(0.179815-0.155545) -> 75.593259 | G13: =(6.2897-5.055156)/(0.2101595-0.155545) -> 22.604693 | U13: =U12/(U12+1) -> 0.88172679
B14: =9/0.86 -> 10.465116 | F14: =(2.26424/1.29)/(6.354/1.29+0.29*5.377/1.29) -> 0.28612986 | G14: =(D4/1.29+0.29*38.04/1.29)/(6.354/1.29+0.29*5.377/1.29) -> 2.9069219 | U14: =30/12.8*(1.05506*1000/252.1654) -> 9.8062497
E15: Mt-CO2/ktoe | G15: =(4.4550516-2.9069218)/(0.28613-0.179815) -> 14.561725 | I15: kt-CO2/Mcal*(Mcal/ktoe) | M15: =26.1/22.5/4 -> 0.29 | U15: =(9.80625-6.2897)/0.155545 -> 22.607927
I16: =B6/B5*(Q9/10^6*10^3)/10^6 -> 2.1100015 | U16: =(9.80625-4.4550516)/0.179815 -> 29.759466
I17: =I16/1000 -> 0.0021100015

Sheet Usage Rate
E1: Without Unit Commitment
D2: Seasonal Change Factors
D3: =COLUMNS(USR) -> 6 | E3: Pattern 1 | F3: Pattern 2 | G3: Pattern 3 | H3: Pattern 4 | I3: Pattern 5 | J3: Pattern 6
D4: Average | E4: =SUM(E5:E369)/365 -> 0.7507523 | F4: =SUM(F5:F369)/365 -> 0.75335729 | G4: =SUM(G5:G369)/365 -> 0.74794521 | H4: =SUM(H5:H369)/365 -> 0.74794521 | I4: =SUM(I5:I369)/365 -> 1 | J4: =SUM(J5:J369)/365 -> 0
D5: 40909 | E5: 0 | F5: 1 | G5: 1 | H5: 1 | I5: 1 | J5: 0
D6: 40910 | E6: 0 | F6: 1 | G6: 1 | H6: 1 | I6: 1 | J6: 0
D7: 40911 | E7: 0 | F7: 1 | G7: 1 | H7: 1 | I7: 1 | J7: 0
D8: 40912 | E8: 0 | F8: 1 | G8: 1 | H8: 1 | I8: 1 | J8: 0
D9: 40913 | E9: 0 | F9: 1 | G9: 1 | H9: 1 | I9: 1 | J9: 0
D10: 40914 | E10: 0 | F10: 1 | G10: 1 | H10: 1 | I10: 1 | J10: 0
D11: 40915 | E11: 0 | F11: 1 | G11: 1 | H11: 1 | I11: 1 | J11: 0
D12: 40916 | E12: 0 | F12: 1 | G12: 1 | H12: 1 | I12: 1 | J12: 0
D13: 40917 | E13: 0 | F13: 1 | G13: 1 | H13: 1 | I13: 1 | J13: 0
D14: 40918 | E14: 0 | F14: 1 | G14: 1 | H14: 1 | I14: 1 | J14: 0
D15: 40919 | E15: 0 | F15: 1 | G15: 1 | H15: 1 | I15: 1 | J15: 0
D16: 40920 | E16: 0 | F16: 1 | G16: 1 | H16: 1 | I16: 1 | J16: 0
... D369: 41274 | E369: 0.016129032 | F369: 1 | G369: 1 | H369: 0.98387097 | I369: 1 | J369: 0
