Workbook
Name AIR: SYS!$C$13
Name ANR: SYS!$I$5:$Q$360
Name ARF: SYS!$I$2:$Q$2
Name BB: TRN!$A$2
Name BLT: TRN!$V$3
Name CO2Max: SYS!$C$9
Name CO2Tax: SYS!$C$8
Name COM: SYS!$H$4
Name D0: SYS!$C$5
Name DB: SYS!$C$6
Name DE: SYS!$C$7
Name DELTA: SYS!$C$12
Name FATX: SYS!$C$14
Name KTmax: TRN!$M$4:$M$464
Name KTmin: TRN!$L$4:$L$464
Name LFCF: SYS!$C$20
Name LOSS: TRN!$K$4:$K$464
Name MAX_SNSP: SYS!$I$3:$Q$3
Name MFLOW: TRN!$H$4:$I$464
Name NMD: SYS!$C$30:$C$41
Name NN: SYS!$G$4
Name O_M_rate: TRN!$U$3
Name QN: SYS!$C$18:$C$19
Name RS: SYS!$C$17
Name SCALE: SYS!$C$16
Name SNN: SYS!$C$18:$C$19
Name SOMAX: SYS!$C$11
Name SOMIN: SYS!$C$10
Name SVR: SYS!$C$15
Name T0: SYS!$C$4
Name TFC: TRN!$J$4:$J$464
Name TI: TRN!$D$4:$E$464
Name UCF: SYS!#REF!
Name XX: TRN!$G$4:$G$464

Sheet SYS
W1: 6 | X1: 47 | Y1: 73 | Z1: 99 | AA1: 176 | AB1: 207 | AC1: 226 | AD1: 227 | AE1: 273 | AF1: 279 | AG1: 325
H2: Area Selection | I2: 1 | J2: 1 | K2: 1 | L2: 1 | M2: 1 | N2: 1 | O2: 1 | P2: 1 | Q2: 1 | R2: (0:Ignored, 1:Normal, 2:Aggregated)
B3: System Settings | G3: Number of Nodes | H3: Number of Areas | I3: -1 | J3: -1 | K3: -1 | L3: -1 | M3: -1 | N3: -1 | O3: -1 | P3: -1 | Q3: -1 | R3: ←SNSP
B4: The Number of Time Steps per Day | C4: 24 | G4: =ROWS(ANR) -> 356 | H4: =COLUMNS(ANR) -> 9 | I4: Hokkaido | J4: Tohoku | K4: Kanto | L4: Chubu | M4: Hokuriku | N4: Kansai | O4: Shikoku | P4: Chugoku | Q4: Kyusyu | R4: CheckSum
B5: The Number of Days per Year | C5: =SUM(NMD) -> 365 | E5: 0 | F5: nab | G5: 0 | H5: 西当別変電所 | I5: 1 | J5: 0 | K5: 0 | L5: 0 | M5: 0 | N5: 0 | O5: 0 | P5: 0 | Q5: 0 | R5: =SUM(I5:Q5) -> 1 | S5: =SUM(R5:R360) -> 356
B6: The Beginning Day | C6: 91 | E6: 1 | F6: nno | G6: 1 | H6: 西野変電所 | I6: 1 | J6: 0 | K6: 0 | L6: 0 | M6: 0 | N6: 0 | O6: 0 | P6: 0 | Q6: 0 | R6: =SUM(I6:Q6) -> 1
B7: The Ending Day | C7: 272 | E7: 2 | F7: nfb | G7: 2 | H7: 西双葉開閉所 | I7: 1 | J7: 0 | K7: 0 | L7: 0 | M7: 0 | N7: 0 | O7: 0 | P7: 0 | Q7: 0 | R7: =SUM(I7:Q7) -> 1
B8: Carbon Tax [kYen/t-CO2] | C8: 0 | D8: 0 | E8: 3 | F8: msb | G8: 3 | H8: 南早来変電所 | I8: 1 | J8: 0 | K8: 0 | L8: 0 | M8: 0 | N8: 0 | O8: 0 | P8: 0 | Q8: 0 | R8: =SUM(I8:Q8) -> 1
B9: Carbon Limit [Mt-CO2/year] | C9: 0 | D9: 10 | E9: 4 | F9: neh | G9: 4 | H9: 苗穂変電所 | I9: 1 | J9: 0 | K9: 0 | L9: 0 | M9: 0 | N9: 0 | O9: 0 | P9: 0 | Q9: 0 | R9: =SUM(I9:Q9) -> 1
B10: Synthetic Oil Production Minimum Level [Mtoe/year] | C10: 0 | E10: 5 | F10: sno | G10: 5 | H10: 篠路変電所 | I10: 1 | J10: 0 | K10: 0 | L10: 0 | M10: 0 | N10: 0 | O10: 0 | P10: 0 | Q10: 0 | R10: =SUM(I10:Q10) -> 1 | AL10: =484*0.74 -> 358.16
B11: Synthetic Oil Production Maximum Level [Mtoe/year] | C11: -1 | E11: 6 | F11: nsp | G11: 6 | H11: 西札幌変電所 | I11: 1 | J11: 0 | K11: 0 | L11: 0 | M11: 0 | N11: 0 | O11: 0 | P11: 0 | Q11: 0 | R11: =SUM(I11:Q11) -> 1
B12: Capacity Reserve Ratio | C12: 0.08 | E12: 7 | F12: ftb | G12: 7 | H12: 双葉開閉所 | I12: 1 | J12: 0 | K12: 0 | L12: 0 | M12: 0 | N12: 0 | O12: 0 | P12: 0 | Q12: 0 | R12: =SUM(I12:Q12) -> 1
B13: Annual Interest Rate | C13: 0.03 | E13: 8 | F13: nmr | G13: 8 | H13: 西室蘭開閉所 | I13: 1 | J13: 0 | K13: 0 | L13: 0 | M13: 0 | N13: 0 | O13: 0 | P13: 0 | Q13: 0 | R13: =SUM(I13:Q13) -> 1
B14: Fixed Assets Tax Rate | C14: 0.014 | E14: 9 | F14: mrn | G14: 9 | H14: 室蘭変電所 | I14: 1 | J14: 0 | K14: 0 | L14: 0 | M14: 0 | N14: 0 | O14: 0 | P14: 0 | Q14: 0 | R14: =SUM(I14:Q14) -> 1
B15: Salvage Value Rate | C15: 0 | E15: 10 | F15: mkj | G15: 10 | H15: 南九条変電所 | I15: 1 | J15: 0 | K15: 0 | L15: 0 | M15: 0 | N15: 0 | O15: 0 | P15: 0 | Q15: 0 | R15: =SUM(I15:Q15) -> 1
B16: scale | C16: 1000 | E16: 11 | F16: not | G16: 11 | H16: 西小樽変電所 | I16: 1 | J16: 0 | K16: 0 | L16: 0 | M16: 0 | N16: 0 | O16: 0 | P16: 0 | Q16: 0 | R16: =SUM(I16:Q16) -> 1
B17: Time Slots Aggregation Number (Divisor of 24) | C17: 3 | E17: 12 | F17: tmk | G17: 12 | H17: 苫小牧変電所 | I17: 1 | J17: 0 | K17: 0 | L17: 0 | M17: 0 | N17: 0 | O17: 0 | P17: 0 | Q17: 0 | R17: =SUM(I17:Q17) -> 1
B18: Maximum No. of Cutting Planes | C18: 200 | E18: 13 | F18: tib | G18: 13 | H18: 追分開閉所 | I18: 1 | J18: 0 | K18: 0 | L18: 0 | M18: 0 | N18: 0 | O18: 0 | P18: 0 | Q18: 0 | R18: =SUM(I18:Q18) -> 1
B19: Maximum No. of Extreme Points of Convex Hull | C19: 200 | E19: 14 | F19: eni | G19: 14 | H19: 恵庭変電所 | I19: 1 | J19: 0 | K19: 0 | L19: 0 | M19: 0 | N19: 0 | O19: 0 | P19: 0 | Q19: 0 | R19: =SUM(I19:Q19) -> 1
B20: LFC Control Reserve Market Fee [Yen/kW] | C20: 0.01 | E20: 15 | F20: msp | G20: 15 | H20: 南札幌変電所 | I20: 1 | J20: 0 | K20: 0 | L20: 0 | M20: 0 | N20: 0 | O20: 0 | P20: 0 | Q20: 0 | R20: =SUM(I20:Q20) -> 1
E21: 16 | F21: keb | G21: 16 | H21: 北江別変電所 | I21: 1 | J21: 0 | K21: 0 | L21: 0 | M21: 0 | N21: 0 | O21: 0 | P21: 0 | Q21: 0 | R21: =SUM(I21:Q21) -> 1
E22: 17 | F22: hkt | G22: 17 | H22: 北斗変換所 | I22: 1 | J22: 0 | K22: 0 | L22: 0 | M22: 0 | N22: 0 | O22: 0 | P22: 0 | Q22: 0 | R22: =SUM(I22:Q22) -> 1
E23: 18 | F23: oon | G23: 18 | H23: 大野変電所 | I23: 1 | J23: 0 | K23: 0 | L23: 0 | M23: 0 | N23: 0 | O23: 0 | P23: 0 | Q23: 0 | R23: =SUM(I23:Q23) -> 1
E24: 19 | F24: nne | G24: 19 | H24: 北七飯変電所 | I24: 1 | J24: 0 | K24: 0 | L24: 0 | M24: 0 | N24: 0 | O24: 0 | P24: 0 | Q24: 0 | R24: =SUM(I24:Q24) -> 1
E25: 20 | F25: ary | G25: 20 | H25: 旭川嵐山開閉所 | I25: 1 | J25: 0 | K25: 0 | L25: 0 | M25: 0 | N25: 0 | O25: 0 | P25: 0 | Q25: 0 | R25: =SUM(I25:Q25) -> 1
E26: 21 | F26: akw | G26: 21 | H26: 旭川変電所 | I26: 1 | J26: 0 | K26: 0 | L26: 0 | M26: 0 | N26: 0 | O26: 0 | P26: 0 | Q26: 0 | R26: =SUM(I26:Q26) -> 1
E27: 22 | F27: nny | G27: 22 | H27: 西名寄変電所 | I27: 1 | J27: 0 | K27: 0 | L27: 0 | M27: 0 | N27: 0 | O27: 0 | P27: 0 | Q27: 0 | R27: =SUM(I27:Q27) -> 1
E28: 23 | F28: nas | G28: 23 | H28: 西旭川変電所 | I28: 1 | J28: 0 | K28: 0 | L28: 0 | M28: 0 | N28: 0 | O28: 0 | P28: 0 | Q28: 0 | R28: =SUM(I28:Q28) -> 1
E29: 24 | F29: ntw | G29: 24 | H29: 西滝川変電所 | I29: 1 | J29: 0 | K29: 0 | L29: 0 | M29: 0 | N29: 0 | O29: 0 | P29: 0 | Q29: 0 | R29: =SUM(I29:Q29) -> 1
B30: January | C30: 31 | D30: =D29+C30 -> 31 | E30: 25 | F30: kar | G30: 25 | H30: 北新得変電所 | I30: 1 | J30: 0 | K30: 0 | L30: 0 | M30: 0 | N30: 0 | O30: 0 | P30: 0 | Q30: 0 | R30: =SUM(I30:Q30) -> 1
B31: February | C31: 28 | D31: =D30+C31 -> 59 | E31: 26 | F31: isz | G31: 26 | H31: 岩清水開閉所 | I31: 1 | J31: 0 | K31: 0 | L31: 0 | M31: 0 | N31: 0 | O31: 0 | P31: 0 | Q31: 0 | R31: =SUM(I31:Q31) -> 1
B32: March | C32: 31 | D32: =D31+C32 -> 90 | E32: 27 | F32: kmm | G32: 27 | H32: 北芽室変電所 | I32: 1 | J32: 0 | K32: 0 | L32: 0 | M32: 0 | N32: 0 | O32: 0 | P32: 0 | Q32: 0 | R32: =SUM(I32:Q32) -> 1
B33: April | C33: 30 | D33: =D32+C33 -> 120 | E33: 28 | F33: nos | G33: 28 | H33: 西音更変電所 | I33: 1 | J33: 0 | K33: 0 | L33: 0 | M33: 0 | N33: 0 | O33: 0 | P33: 0 | Q33: 0 | R33: =SUM(I33:Q33) -> 1
B34: May | C34: 31 | D34: =D33+C34 -> 151 | E34: 29 | F34: umb | G34: 29 | H34: 宇円別変電所 | I34: 1 | J34: 0 | K34: 0 | L34: 0 | M34: 0 | N34: 0 | O34: 0 | P34: 0 | Q34: 0 | R34: =SUM(I34:Q34) -> 1
B35: June | C35: 30 | D35: =D34+C35 -> 181 | E35: 30 | F35: hkr | G35: 30 | H35: 東釧路変電所 | I35: 1 | J35: 0 | K35: 0 | L35: 0 | M35: 0 | N35: 0 | O35: 0 | P35: 0 | Q35: 0 | R35: =SUM(I35:Q35) -> 1
B36: July | C36: 31 | D36: =D35+C36 -> 212 | E36: 31 | F36: nhb | G36: 31 | H36: 西春別変電所 | I36: 1 | J36: 0 | K36: 0 | L36: 0 | M36: 0 | N36: 0 | O36: 0 | P36: 0 | Q36: 0 | R36: =SUM(I36:Q36) -> 1
B37: August | C37: 31 | D37: =D36+C37 -> 243 | E37: 32 | F37: hkd | G37: 32 | H37: 電発函館変換所 | I37: 1 | J37: 0 | K37: 0 | L37: 0 | M37: 0 | N37: 0 | O37: 0 | P37: 0 | Q37: 0 | R37: =SUM(I37:Q37) -> 1
B38: September | C38: 30 | D38: =D37+C38 -> 273 | E38: 33 | F38: uwk | G38: 33 | H38: 上北変電所 | I38: 0 | J38: 1 | K38: 0 | L38: 0 | M38: 0 | N38: 0 | O38: 0 | P38: 0 | Q38: 0 | R38: =SUM(I38:Q38) -> 1
B39: October | C39: 31 | D39: =D38+C39 -> 304 | E39: 34 | F39: iwt | G39: 34 | H39: 岩手変電所 | I39: 0 | J39: 1 | K39: 0 | L39: 0 | M39: 0 | N39: 0 | O39: 0 | P39: 0 | Q39: 0 | R39: =SUM(I39:Q39) -> 1
B40: November | C40: 30 | D40: =D39+C40 -> 334 | E40: 35 | F40: myg | G40: 35 | H40: 宮城変電所 | I40: 0 | J40: 1 | K40: 0 | L40: 0 | M40: 0 | N40: 0 | O40: 0 | P40: 0 | Q40: 0 | R40: =SUM(I40:Q40) -> 1
...

Sheet TRN
A1: Number of Branches | L1: MAX δ
A2: =ROWS(TI) -> 461 | H2: Node2->Node1 | I2: Node1->Node2 | L2: =PI()/12 -> 0.26179939 | U2: O&M rate | V2: 耐用年数 | Z2: yen | AA2: kW | AB2: km | AG2: GW | AH2: 10^8yen/ 2GW/km
A3: BRN # | B3: Code1 | C3: Code2 | D3: Node1 | E3: Node2 | F3: Distance[km] | G3: X [1000MVAベース] | H3: Maximum Flow1 | I3: Maximum Flow2 | J3: Construction Cost [kYen/kW] | K3: Loss | L3: Minimum Capacity [GW] | M3: Maximum Capacity [GW] | N3: BRN NAME | O3: Node1 | P3: Node2 | U3: 0.01 | V3: 25 | W3: =440*10^6*131 -> 57640000000 | Z3: =W3 -> 57640000000 | AA3: =700*10^3 -> 700000 | AB3: 244 | AC3: =Z3/AA3/AB3 -> 337.47073 | AD3: =Z3/AA3 -> 82342.857 | AE3: =Z3/AA3/AB3 -> 337.47073 | AG3: =AA3/10^6 -> 0.7 | AH3: =(Z3-314*10^8)*(2/AG3)/AB3/10^8 -> 3.0725995
A4: 0 | B4: hkd | C4: uwk | D4: =VLOOKUP(B4,SYS!$F$5:$G$360,2,FALSE) -> 32 | E4: =VLOOKUP(C4,SYS!$F$5:$G$360,2,FALSE) -> 33 | F4: 45 | G4: 0 | H4: -1 | I4: -1 | J4: 0 | K4: =F4*0.0002 -> 0.009 | L4: 0.6 | M4: 0.6 | N4: 北本連系線 | O4: =VLOOKUP(TRN!D4,SYS!$G$5:$H$360,2,FALSE) -> 電発函館変換所 | P4: =VLOOKUP(TRN!E4,SYS!$G$5:$H$360,2,FALSE) -> 上北変電所 | R4: Unit Construction Cost for Upper [Yen/kW/km] | T4: 北海道->東北 | W4: =48*1000*500*131 -> 3144000000 | Z4: =600*10^6*131 -> 78600000000 | AA4: =1000*10^3 -> 1000000 | AB4: 260 | AC4: =Z4/AA4/AB4 -> 302.30769 | AD4: =Z4/AA4 -> 78600 | AE4: =Z4/AA4/AB4 -> 302.30769 | AG4: =AA4/10^6 -> 1 | AH4: =(Z4-314*10^8)*(2/AG4)/AB4/10^8 -> 3.6307692
A5: 1 | B5: sma | C5: miw | D5: =VLOOKUP(B5,SYS!$F$5:$G$360,2,FALSE) -> 37 | E5: =VLOOKUP(C5,SYS!$F$5:$G$360,2,FALSE) -> 63 | F5: 21.903165 | G5: =$L$2/L5 -> 0.00721 | H5: =6.31-L19 -> 4.054 | I5: =10.28-M19 -> 8.024 | J5: 0 | K5: =F5*0.0002 -> 0.004380633 | L5: 36.310595 | M5: 36.310595 | N5: 相馬双葉幹線 | O5: =VLOOKUP(TRN!D5,SYS!$G$5:$H$360,2,FALSE) -> 南相馬変電所 | P5: =VLOOKUP(TRN!E5,SYS!$G$5:$H$360,2,FALSE) -> 南いわき開閉所 | R5: 0 | T5: 東北->東京 | V5: v1 | W5: =430*10^8/300000/122 -> 1174.8634 | Z5: =1350*10^6*131 -> 176850000000 | AA5: =1400*10^3 -> 1400000 | AB5: 600 | AC5: =Z5/AA5/AB5 -> 210.53571 | AD5: =Z5/AA5 -> 126321.43 | AE5: =Z5/AA5/AB5 -> 210.53571 | AG5: =AA5/10^6 -> 1.4 | AH5: =(Z5-314*10^8)*(2/AG5)/AB5/10^8 -> 3.4630952
A6: 2 | B6: fkm | C6: mfm | D6: =VLOOKUP(B6,SYS!$F$5:$G$360,2,FALSE) -> 139 | E6: =VLOOKUP(C6,SYS!$F$5:$G$360,2,FALSE) -> 202 | F6: 0 | G6: 0 | H6: -1 | I6: -1 | J6: 0 | K6: =F6*0.0002 -> 0 | L6: 0.3 | M6: 0.3 | N6: 南福光連系所 | O6: =VLOOKUP(TRN!D6,SYS!$G$5:$H$360,2,FALSE) -> 南福光連係所 | P6: =VLOOKUP(TRN!E6,SYS!$G$5:$H$360,2,FALSE) -> 南福光変電所 | R6: 500 | T6: 中部->北陸 | V6: 0.044 | W6: 1200 yen/kW/km | Z6: =1400*10^6*131 -> 183400000000 | AA6: =1400*10^3 -> 1400000 | AB6: 600 | AC6: =Z6/AA6/AB6 -> 218.33333 | AD6: =Z6/AA6 -> 131000 | AE6: =Z6/AA6/AB6 -> 218.33333 | AG6: =AA6/10^6 -> 1.4 | AH6: =(Z6-314*10^8)*(2/AG6)/AB6/10^8 -> 3.6190476
A7: 3 | B7: ech | C7: ryn | D7: =VLOOKUP(B7,SYS!$F$5:$G$360,2,FALSE) -> 199 | E7: =VLOOKUP(C7,SYS!$F$5:$G$360,2,FALSE) -> 221 | F7: 104.83015 | G7: =$L$2/L7 -> 0.0395 | H7: 1.5 | I7: 1.9 | J7: 0 | K7: =F7*0.0002 -> 0.02096603 | L7: 6.6278326 | M7: 6.6278326 | N7: 越前嶺南線 | O7: =VLOOKUP(TRN!D7,SYS!$G$5:$H$360,2,FALSE) -> 越前変電所 | P7: =VLOOKUP(TRN!E7,SYS!$G$5:$H$360,2,FALSE) -> 嶺南変電所 | R7: 500 | T7: 北陸->関西 | W7: =1200*700*10^3*140 -> 117600000000 | Z7: =700*10^6*131 -> 91700000000 | AA7: =2000*10^3 -> 2000000 | AB7: 64 | AC7: =Z7/AA7/AB7 -> 716.40625 | AD7: =Z7/AA7 -> 45850 | AE7: =Z7/AA7/AB7 -> 716.40625 | AG7: =AA7/10^6 -> 2 | AH7: =(Z7-314*10^8)*(2/AG7)/AB7/10^8 -> 9.421875
A8: 4 | B8: mie | C8: hom | D8: =VLOOKUP(B8,SYS!$F$5:$G$360,2,FALSE) -> 133 | E8: =VLOOKUP(C8,SYS!$F$5:$G$360,2,FALSE) -> 215 | F8: 17.914013 | G8: =$L$2/L8 -> 0.00675 | H8: 2.5 | I8: 1.24 | J8: 0 | K8: =F8*0.0002 -> 0.0035828025 | L8: 38.785094 | M8: 38.785094 | N8: 三重東近江線 | O8: =VLOOKUP(TRN!D8,SYS!$G$5:$H$360,2,FALSE) -> 三重開閉所 | P8: =VLOOKUP(TRN!E8,SYS!$G$5:$H$360,2,FALSE) -> 東近江開閉所 | R8: 500 | T8: 中部->関西 | V8: v2 | W8: =J27*300000 -> 14716626
A9: 5 | B9: kkt | C9: ana | D9: =VLOOKUP(B9,SYS!$F$5:$G$360,2,FALSE) -> 223 | E9: =VLOOKUP(C9,SYS!$F$5:$G$360,2,FALSE) -> 260 | F9: 0 | G9: 0 | H9: -1 | I9: -1 | J9: 0 | K9: =F9*0.0002 -> 0 | L9: 1.4 | M9: 1.4 | N9: 阿南紀北直流幹線 | O9: =VLOOKUP(TRN!D9,SYS!$G$5:$H$360,2,FALSE) -> 紀北変換所 | P9: =VLOOKUP(TRN!E9,SYS!$G$5:$H$360,2,FALSE) -> 阿南変換所 | R9: 500 | T9: 関西->四国 | V9: =1/0.03 -> 33.333333 | W9: =J21*300000 -> 29437443
A10: 6 | B10: san | C10: hok | D10: =VLOOKUP(B10,SYS!$F$5:$G$360,2,FALSE) -> 258 | E10: =VLOOKUP(C10,SYS!$F$5:$G$360,2,FALSE) -> 286 | F10: 105.49363 | G10: =$L$2/L10 -> 0.03975 | H10: 1.2 | I10: 1.2 | J10: 0 | K10: =F10*0.0002 -> 0.021098726 | L10: 6.5861481 | M10: 6.5861481 | N10: 本四連系線 | O10: =VLOOKUP(TRN!D10,SYS!$G$5:$H$360,2,FALSE) -> 讃岐変電所 | P10: =VLOOKUP(TRN!E10,SYS!$G$5:$H$360,2,FALSE) -> 東岡山（変） | R10: 500 | T10: 四国->中国 | W10: =8*10^8/(J20*1000) -> 7367.5917
A11: 7 | B11: yzk | C11: cht | D11: =VLOOKUP(B11,SYS!$F$5:$G$360,2,FALSE) -> 217 | E11: =VLOOKUP(C11,SYS!$F$5:$G$360,2,FALSE) -> 281 | F11: 70.329087 | G11: =$L$2/L11 -> 0.0265 | H11: 2.1 | I11: 1.39 | J11: 0 | K11: =F11*0.0002 -> 0.014065817 | L11: 9.8792222 | M11: 9.8792222 | N11: 山崎智頭線 | O11: =VLOOKUP(TRN!D11,SYS!$G$5:$H$360,2,FALSE) -> 山崎開閉所 | P11: =VLOOKUP(TRN!E11,SYS!$G$5:$H$360,2,FALSE) -> 智頭（変） | R11: 500 | T11: 関西->中国 | V11: v3 | Y11: 567 | Z11: =(135.27*Y11+47805)*2*10^6/10^8 -> 2490.0618
A12: 8 | B12: nba | C12: hok | D12: =VLOOKUP(B12,SYS!$F$5:$G$360,2,FALSE) -> 209 | E12: =VLOOKUP(C12,SYS!$F$5:$G$360,2,FALSE) -> 286 | F12: 75.636943 | G12: =$L$2/L12 -> 0.0285 | H12: 2.1 | I12: 1.39 | J12: 0 | K12: =F12*0.0002 -> 0.015127389 | L12: 9.1859434 | M12: 9.1859434 | N12: 西播岡山線 | O12: =VLOOKUP(TRN!D12,SYS!$G$5:$H$360,2,FALSE) -> 西播変電所 | P12: =VLOOKUP(TRN!E12,SYS!$G$5:$H$360,2,FALSE) -> 東岡山（変） | T12: 関西->中国 | V12: 1.03 | Y12: 425 | Z12: =(135.27*Y12+47805)*2*10^6/10^8 -> 2105.895
A13: 9 | B13: sym | C13: kky | D13: =VLOOKUP(B13,SYS!$F$5:$G$360,2,FALSE) -> 278 | E13: =VLOOKUP(C13,SYS!$F$5:$G$360,2,FALSE) -> 308 | F13: 55.86518 | G13: =$L$2/L13 -> 0.02105 | H13: 2.78 | I13: 0.32 | J13: 0 | K13: =F13*0.0002 -> 0.011173036 | L13: 12.437026 | M13: 12.437026 | N13: 関門連系線 | O13: =VLOOKUP(TRN!D13,SYS!$G$5:$H$360,2,FALSE) -> 新山口（変） | P13: =VLOOKUP(TRN!E13,SYS!$G$5:$H$360,2,FALSE) -> 北九州変電所 | T13: 中国->九州 | V13: 均等化年経費率 | Y13: 480 | Z13: =(135.27*Y13+47805)*2*10^6/10^8 -> 2254.692
A14: 10 | B14: kfj | C14: hse | D14: =VLOOKUP(B14,SYS!$F$5:$G$360,2,FALSE) -> 89 | E14: =VLOOKUP(C14,SYS!$F$5:$G$360,2,FALSE) -> 141 | F14: 100 | G14: 0 | H14: -1 | I14: -1 | J14: 0 | K14: =F14*0.0002 -> 0.02 | L14: 0.6 | M14: 0.6 | N14: 佐久間FC | O14: =VLOOKUP(TRN!D14,SYS!$G$5:$H$360,2,FALSE) -> 新富士変電所 | P14: =VLOOKUP(TRN!E14,SYS!$G$5:$H$360,2,FALSE) -> 東栄変電所 | R14: =0.6*0.6/3 -> 0.12 | T14: 東京->中部 | V14: =1/BLT*(1-V6*(V9-BLT/(V12^BLT-1)))+V6+O_M_rate -> 0.075560878 | Y14: 720 | Z14: =(135.27*Y14+47805)*2*10^6/10^8 -> 2903.988
A15: 11 | B15: kfj | C15: his | D15: =VLOOKUP(B15,SYS!$F$5:$G$360,2,FALSE) -> 89 | E15: =VLOOKUP(C15,SYS!$F$5:$G$360,2,FALSE) -> 195 | F15: 100 | G15: 0 | H15: -1 | I15: -1 | J15: 0 | K15: =F15*0.0002 -> 0.02 | L15: 0.9 | M15: 0.9 | N15: 東清水FC | O15: =VLOOKUP(TRN!D15,SYS!$G$5:$H$360,2,FALSE) -> 新富士変電所 | P15: =VLOOKUP(TRN!E15,SYS!$G$5:$H$360,2,FALSE) -> 東清水変電所 | R15: =0.6*0.9/3 -> 0.18 | T15: 東京->中部 | Y15: 296 | Z15: =(135.27*Y15+47805)*2*10^6/10^8 -> 1756.8984
A16: 12 | B16: hkt | C16: ibt | D16: =VLOOKUP(B16,SYS!$F$5:$G$360,2,FALSE) -> 17 | E16: =VLOOKUP(C16,SYS!$F$5:$G$360,2,FALSE) -> 60 | F16: 122 | G16: 0 | H16: -1 | I16: -1 | J16: 0 | K16: =F16*0.0002 -> 0.0244 | L16: 0.3 | M16: 0.3 | N16: 北本連系線2 | O16: =VLOOKUP(TRN!D16,SYS!$G$5:$H$360,2,FALSE) -> 北斗変換所 | P16: =VLOOKUP(TRN!E16,SYS!$G$5:$H$360,2,FALSE) -> 今別変換所 | T16: 北海道->東北 | Y16: 429 | Z16: =(135.27*Y16+47805)*2*10^6/10^8 -> 2116.7166
A17: 13 | B17: ssi | C17: nks | D17: =VLOOKUP(B17,SYS!$F$5:$G$360,2,FALSE) -> 132 | E17: =VLOOKUP(C17,SYS!$F$5:$G$360,2,FALSE) -> 166 | F17: 5 | G17: 0 | H17: -1 | I17: -1 | J17: 0 | K17: =F17*0.0002 -> 0.001 | L17: 0.6 | M17: 0.6 | N17: 新信濃1FC | O17: =VLOOKUP(TRN!D17,SYS!$G$5:$H$360,2,FALSE) -> 新信濃変電所 | P17: =VLOOKUP(TRN!E17,SYS!$G$5:$H$360,2,FALSE) -> 中信変電所 | T17: 東京->中部 | Y17: 424 | Z17: =(135.27*Y17+47805)*2*10^6/10^8 -> 2103.1896
A18: 14 | B18: ssi | C18: hid | D18: =VLOOKUP(B18,SYS!$F$5:$G$360,2,FALSE) -> 132 | E18: =VLOOKUP(C18,SYS!$F$5:$G$360,2,FALSE) -> 198 | F18: 89 | G18: 0 | H18: -1 | I18: -1 | J18: 0 | K18: =F18*0.0002 -> 0.0178 | L18: 0.9 | M18: 0.9 | N18: 新信濃2FC | O18: =VLOOKUP(TRN!D18,SYS!$G$5:$H$360,2,FALSE) -> 新信濃変電所 | P18: =VLOOKUP(TRN!E18,SYS!$G$5:$H$360,2,FALSE) -> 飛騨変換所 | R18: =0.6*1.5/3 -> 0.3 | T18: 東京->中部 | Y18: 466 | Z18: =(135.27*Y18+47805)*2*10^6/10^8 -> 2216.8164
A19: 15 | B19: sma | C19: sfu | D19: =VLOOKUP(B19,SYS!$F$5:$G$360,2,FALSE) -> 37 | E19: =VLOOKUP(C19,SYS!$F$5:$G$360,2,FALSE) -> 62 | F19: 20 | G19: =$L$2/L19 -> 0.11604583 | H19: -1 | I19: -1 | J19: 0 | K19: =F19*0.0002 -> 0.004 | L19: 2.256 | M19: 2.256 | N19: いわき幹線 | O19: =VLOOKUP(TRN!D19,SYS!$G$5:$H$360,2,FALSE) -> 南相馬変電所 | P19: =VLOOKUP(TRN!E19,SYS!$G$5:$H$360,2,FALSE) -> 新福島変電所 | T19: 東北→東京
A20: 16 | B20: not | C20: kzk | D20: =VLOOKUP(B20,SYS!$F$5:$G$360,2,FALSE) -> 11 | E20: =VLOOKUP(C20,SYS!$F$5:$G$360,2,FALSE) -> 82 | F20: 750 | G20: 0 | H20: -1 | I20: -1 | J20: =(T20+30000)/1000*0.7 -> 108.58365 | K20: 0.01 | L20: 0 | M20: 10 | N20: 北海道→東北 | O20: =VLOOKUP(TRN!D20,SYS!$G$5:$H$360,2,FALSE) -> 西小樽変電所 | P20: =VLOOKUP(TRN!E20,SYS!$G$5:$H$360,2,FALSE) -> 柏崎刈羽原子力 | T20: =F20*124.51+31737 -> 125119.5 | U20: 北海道→東京 | Y20: 172 | Z20: =(135.27*Y20+47805)*2*10^6/10^8 -> 1421.4288
A21: 17 | B21: tmk | C21: fkn | D21: =VLOOKUP(B21,SYS!$F$5:$G$360,2,FALSE) -> 12 | E21: =VLOOKUP(C21,SYS!$F$5:$G$360,2,FALSE) -> 61 | F21: 630 | G21: 0 | H21: -1 | I21: -1 | J21: =(T21+30000)/1000*0.7 -> 98.12481 | K21: 0.01 | L21: 0 | M21: 10 | N21: 北海道→東京 | O21: =VLOOKUP(TRN!D21,SYS!$G$5:$H$360,2,FALSE) -> 苫小牧変電所 | P21: =VLOOKUP(TRN!E21,SYS!$G$5:$H$360,2,FALSE) -> 旧福島第二原子力 | T21: =F21*124.51+31737 -> 110178.3 | U21: 北海道→東京 | Y21: 1120 | Z21: =(135.27*Y21+47805)*2*10^6/10^8 -> 3986.148
A22: 18 | B22: akt | C22: kzk | D22: =VLOOKUP(B22,SYS!$F$5:$G$360,2,FALSE) -> 40 | E22: =VLOOKUP(C22,SYS!$F$5:$G$360,2,FALSE) -> 82 | F22: 300 | G22: 0 | H22: -1 | I22: -1 | J22: =(T22+30000)/1000*0.7 -> 69.363 | K22: 0.01 | L22: 0 | M22: 10 | N22: 東北→東京 | O22: =VLOOKUP(TRN!D22,SYS!$G$5:$H$360,2,FALSE) -> 秋田変電所 | P22: =VLOOKUP(TRN!E22,SYS!$G$5:$H$360,2,FALSE) -> 柏崎刈羽原子力 | T22: =F22*124.51+31737 -> 69090 | U22: 東北→東京 | V22: 39.81344155846961, 140.08600868575846 | W22: 37.421658772924616, 138.5955646412592
B23: kzk | C23: sks | D23: =VLOOKUP(B23,SYS!$F$5:$G$360,2,FALSE) -> 82 | E23: =VLOOKUP(C23,SYS!$F$5:$G$360,2,FALSE) -> 168 | F23: 45 | G23: 0 | H23: -1 | I23: -1 | J23: =(T23+30000)/1000*0.7 -> 47.137965 | K23: 0.01 | L23: 0 | M23: 10 | N23: 東京→中部（柏崎） | O23: =VLOOKUP(TRN!D23,SYS!$G$5:$H$360,2,FALSE) -> 柏崎刈羽原子力 | P23: =VLOOKUP(TRN!E23,SYS!$G$5:$H$360,2,FALSE) -> 新北信変電所 | T23: =F23*124.51+31737 -> 37339.95 | U23: 東京→中部
A24: 19 | B24: sks | C24: mdk | D24: =VLOOKUP(B24,SYS!$F$5:$G$360,2,FALSE) -> 168 | E24: =VLOOKUP(C24,SYS!$F$5:$G$360,2,FALSE) -> 219 | F24: 420 | G24: 0 | H24: -1 | I24: -1 | J24: =(T24+30000)/1000*0.7 -> 79.82184 | K24: 0.01 | L24: 0 | M24: 0 | N24: 東京→関西（日本海） | O24: =VLOOKUP(TRN!D24,SYS!$G$5:$H$360,2,FALSE) -> 新北信変電所 | P24: =VLOOKUP(TRN!E24,SYS!$G$5:$H$360,2,FALSE) -> 舞鶴火力 | T24: =F24*124.51+31737 -> 84031.2 | U24: 東京→関西（日本海） | V24: 37.421658772924616, 138.5955646412592 | W24: 35.5029669878051, 135.39713661369862
A25: 20 | B25: htn | C25: mta | D25: =VLOOKUP(B25,SYS!$F$5:$G$360,2,FALSE) -> 92 | E25: =VLOOKUP(C25,SYS!$F$5:$G$360,2,FALSE) -> 151 | F25: 380 | G25: 0 | H25: -1 | I25: -1 | J25: =(T25+30000)/1000*0.7 -> 76.33556 | K25: 0.01 | L25: 0 | M25: 10 | N25: 東京→関西（太平洋） | O25: =VLOOKUP(TRN!D25,SYS!$G$5:$H$360,2,FALSE) -> 新秦野変電所 | P25: =VLOOKUP(TRN!E25,SYS!$G$5:$H$360,2,FALSE) -> 尾鷲三田変電所 | T25: =F25*124.51+31737 -> 79050.8 | U25: 東京→関西（太平洋） | V25: 35.40066582144089, 139.2250703092658 | W25: 34.071374924761415, 136.17701106893637
A26: 21 | B26: kkt | C26: ana | D26: =VLOOKUP(B26,SYS!$F$5:$G$360,2,FALSE) -> 223 | E26: =VLOOKUP(C26,SYS!$F$5:$G$360,2,FALSE) -> 260 | F26: 85 | G26: 0 | H26: -1 | I26: -1 | J26: =(T26+30000)/1000*0.7 -> 50.624245 | K26: 0.01 | L26: 0 | M26: 10 | N26: 関西→四国 | O26: =VLOOKUP(TRN!D26,SYS!$G$5:$H$360,2,FALSE) -> 紀北変換所 | P26: =VLOOKUP(TRN!E26,SYS!$G$5:$H$360,2,FALSE) -> 阿南変換所 | T26: =F26*124.51+31737 -> 42320.35 | U26: 関西→四国
A27: 22 | B27: ika | C27: hky | D27: =VLOOKUP(B27,SYS!$F$5:$G$360,2,FALSE) -> 262 | E27: =VLOOKUP(C27,SYS!$F$5:$G$360,2,FALSE) -> 311 | F27: 67 | G27: 0 | H27: -1 | I27: -1 | J27: =(T27+30000)/1000*0.7 -> 49.055419 | K27: 0.01 | L27: 0 | M27: 10 | N27: 四国→九州 | O27: =VLOOKUP(TRN!D27,SYS!$G$5:$H$360,2,FALSE) -> 伊方原子力 | P27: =VLOOKUP(TRN!E27,SYS!$G$5:$H$360,2,FALSE) -> 東九州変電所 | T27: =F27*124.51+31737 -> 40079.17 | U27: 四国→九州
A28: 23 | B28: ryn | C28: fko | D28: =VLOOKUP(B28,SYS!$F$5:$G$360,2,FALSE) -> 221 | E28: =VLOOKUP(C28,SYS!$F$5:$G$360,2,FALSE) -> 327 | F28: 600 | G28: 0 | H28: -1 | I28: -1 | J28: =(T28+30000)/1000*0.7 -> 95.5101 | K28: 0.01 | L28: 0 | M28: 10 | N28: 関西→九州 | O28: =VLOOKUP(TRN!D28,SYS!$G$5:$H$360,2,FALSE) -> 嶺南変電所 | P28: =VLOOKUP(TRN!E28,SYS!$G$5:$H$360,2,FALSE) -> 東福岡変電所 | T28: =F28*124.51+31737 -> 106443 | U28: 関西→九州
A29: 24 | B29: nab | C29: nno | D29: =VLOOKUP(B29,SYS!$F$5:$G$360,2,FALSE) -> 0 | E29: =VLOOKUP(C29,SYS!$F$5:$G$360,2,FALSE) -> 1 | F29: 33 | G29: 0.13011 | H29: -1 | I29: -1 | J29: 0 | K29: =F29*0.0002 -> 0.0066 | L29: 1.809 | M29: 1.809 | N29: 道央北幹線 | O29: =VLOOKUP(TRN!D29,SYS!$G$5:$H$360,2,FALSE) -> 西当別変電所 | P29: =VLOOKUP(TRN!E29,SYS!$G$5:$H$360,2,FALSE) -> 西野変電所 | T29: 1.5564227 | U29: 0.89935636
A30: 25 | B30: eni | C30: neh | D30: =VLOOKUP(B30,SYS!$F$5:$G$360,2,FALSE) -> 14 | E30: =VLOOKUP(C30,SYS!$F$5:$G$360,2,FALSE) -> 4 | F30: 41 | G30: 0.15932 | H30: -1 | I30: -1 | J30: 0 | K30: =F30*0.0002 -> 0.0082 | L30: 1.356 | M30: 1.356 | N30: 道央西幹線 | O30: =VLOOKUP(TRN!D30,SYS!$G$5:$H$360,2,FALSE) -> 恵庭変電所 | P30: =VLOOKUP(TRN!E30,SYS!$G$5:$H$360,2,FALSE) -> 苗穂変電所 | T30: 1.4691763 | U30: 1.5479588
A31: 26 | B31: msb | C31: nfb | D31: =VLOOKUP(B31,SYS!$F$5:$G$360,2,FALSE) -> 3 | E31: =VLOOKUP(C31,SYS!$F$5:$G$360,2,FALSE) -> 2 | F31: 74 | G31: 0.29012 | H31: -1 | I31: -1 | J31: 0 | K31: =F31*0.0002 -> 0.0148 | L31: 1.197 | M31: 1.197 | N31: 道央南幹線 | O31: =VLOOKUP(TRN!D31,SYS!$G$5:$H$360,2,FALSE) -> 南早来変電所 | P31: =VLOOKUP(TRN!E31,SYS!$G$5:$H$360,2,FALSE) -> 西双葉開閉所 | T31: 2.1672625 | U31: 1.4951921
A32: 27 | B32: msb | C32: nab | D32: =VLOOKUP(B32,SYS!$F$5:$G$360,2,FALSE) -> 3 | E32: =VLOOKUP(C32,SYS!$F$5:$G$360,2,FALSE) -> 0 | F32: 92 | G32: 0.35852 | H32: -1 | I32: -1 | J32: 0 | K32: =F32*0.0002 -> 0.0184 | L32: 1.892 | M32: 1.892 | N32: 道央東幹線 | O32: =VLOOKUP(TRN!D32,SYS!$G$5:$H$360,2,FALSE) -> 南早来変電所 | P32: =VLOOKUP(TRN!E32,SYS!$G$5:$H$360,2,FALSE) -> 西当別変電所 | T32: 1.2601353 | U32: 0.94172972
A33: 28 | B33: nab | C33: neh | D33: =VLOOKUP(B33,SYS!$F$5:$G$360,2,FALSE) -> 0 | E33: =VLOOKUP(C33,SYS!$F$5:$G$360,2,FALSE) -> 4 | F33: 19 | G33: =$L$2/L33 -> 0.20485085 | H33: -1 | I33: -1 | J33: 0 | K33: =F33*0.0002 -> 0.0038 | L33: 1.278 | M33: 1.278 | N33: 苗穂北線 | O33: =VLOOKUP(TRN!D33,SYS!$G$5:$H$360,2,FALSE) -> 西当別変電所 | P33: =VLOOKUP(TRN!E33,SYS!$G$5:$H$360,2,FALSE) -> 苗穂変電所 | Q33: 0.639 | T33: 1.3559539 | U33: 2.0384274
A34: 29 | B34: nab | C34: sno | D34: =VLOOKUP(B34,SYS!$F$5:$G$360,2,FALSE) -> 0 | E34: =VLOOKUP(C34,SYS!$F$5:$G$360,2,FALSE) -> 5 | F34: 17 | G34: 0.18806 | H34: -1 | I34: -1 | J34: 0 | K34: =F34*0.0002 -> 0.0034 | L34: 0.639 | M34: 0.639 | N34: 篠路線 | O34: =VLOOKUP(TRN!D34,SYS!$G$5:$H$360,2,FALSE) -> 西当別変電所 | P34: =VLOOKUP(TRN!E34,SYS!$G$5:$H$360,2,FALSE) -> 篠路変電所 | T34: 3.1502744 | U34: 3.3226684
A35: 30 | B35: nsp | C35: sno | D35: =VLOOKUP(B35,SYS!$F$5:$G$360,2,FALSE) -> 6 | E35: =VLOOKUP(C35,SYS!$F$5:$G$360,2,FALSE) -> 5 | F35: 9 | G35: 0.09992 | H35: -1 | I35: -1 | J35: 0 | K35: =F35*0.0002 -> 0.0018 | L35: 0.276 | M35: 0.276 | N35: 西札幌線 | O35: =VLOOKUP(TRN!D35,SYS!$G$5:$H$360,2,FALSE) -> 西札幌変電所 | P35: =VLOOKUP(TRN!E35,SYS!$G$5:$H$360,2,FALSE) -> 篠路変電所 | T35: 4.7656234 | U35: 364.15263
A36: 31 | B36: nno | C36: nsp | D36: =VLOOKUP(B36,SYS!$F$5:$G$360,2,FALSE) -> 1 | E36: =VLOOKUP(C36,SYS!$F$5:$G$360,2,FALSE) -> 6 | F36: 10 | G36: 0.11697 | H36: -1 | I36: -1 | J36: 0 | K36: =F36*0.0002 -> 0.002 | L36: 0.558 | M36: 0.558 | N36: 室蘭西幹線1 | O36: =VLOOKUP(TRN!D36,SYS!$G$5:$H$360,2,FALSE) -> 西野変電所 | P36: =VLOOKUP(TRN!E36,SYS!$G$5:$H$360,2,FALSE) -> 西札幌変電所 | T36: 2.1355192 | U36: 6678.9815
A37: 32 | B37: ftb | C37: neh | D37: =VLOOKUP(B37,SYS!$F$5:$G$360,2,FALSE) -> 7 | E37: =VLOOKUP(C37,SYS!$F$5:$G$360,2,FALSE) -> 4 | F37: 42 | G37: 0.48493 | H37: -1 | I37: -1 | J37: 0 | K37: =F37*0.0002 -> 0.0084 | L37: 0.555 | M37: 0.555 | N37: 室蘭西幹線2 | O37: =VLOOKUP(TRN!D37,SYS!$G$5:$H$360,2,FALSE) -> 双葉開閉所 | P37: =VLOOKUP(TRN!E37,SYS!$G$5:$H$360,2,FALSE) -> 苗穂変電所 | T37: 3323.2712 | U37: 5.2022465
A38: 33 | B38: nmr | C38: ftb | D38: =VLOOKUP(B38,SYS!$F$5:$G$360,2,FALSE) -> 8 | E38: =VLOOKUP(C38,SYS!$F$5:$G$360,2,FALSE) -> 7 | F38: 45 | G38: 0.52346 | H38: -1 | I38: -1 | J38: 0 | K38: =F38*0.0002 -> 0.009 | L38: 0.478 | M38: 0.478 | N38: 室蘭西幹線3 | O38: =VLOOKUP(TRN!D38,SYS!$G$5:$H$360,2,FALSE) -> 西室蘭開閉所 | P38: =VLOOKUP(TRN!E38,SYS!$G$5:$H$360,2,FALSE) -> 双葉開閉所 | T38: 5.0252826 | U38: 3.923306
A39: 34 | B39: nmr | C39: mrn | D39: =VLOOKUP(B39,SYS!$F$5:$G$360,2,FALSE) -> 8 | E39: =VLOOKUP(C39,SYS!$F$5:$G$360,2,FALSE) -> 9 | F39: 7 | G39: 0.08037 | H39: -1 | I39: -1 | J39: 0 | K39: =F39*0.0002 -> 0.0014 | L39: 0.368 | M39: 0.368 | N39: 室蘭西幹線4 | O39: =VLOOKUP(TRN!D39,SYS!$G$5:$H$360,2,FALSE) -> 西室蘭開閉所 | P39: =VLOOKUP(TRN!E39,SYS!$G$5:$H$360,2,FALSE) -> 室蘭変電所 | T39: 5.3510481 | U39: 6.1656098
A40: 35 | B40: nno | C40: mkj | D40: =VLOOKUP(B40,SYS!$F$5:$G$360,2,FALSE) -> 1 | E40: =VLOOKUP(C40,SYS!$F$5:$G$360,2,FALSE) -> 10 | F40: 16 | G40: =$L$2/L40 -> 0.61311332 | H40: -1 | I40: -1 | J40: 0 | K40: =F40*0.0002 -> 0.0032 | L40: 0.427 | M40: 0.427 | N40: 南九条線 | O40: =VLOOKUP(TRN!D40,SYS!$G$5:$H$360,2,FALSE) -> 西野変電所 | P40: =VLOOKUP(TRN!E40,SYS!$G$5:$H$360,2,FALSE) -> 南九条変電所 | T40: 2.9491075 | U40: 12.835238
...
